Workbook

Sheet 실행
B1: 손해율 월말 집계
B3: ① 입력 (노란 칸만) | D3: 자동변환
B4: 마감 기준월 | C4: 202509 | D4: =IFERROR(--TRIM(C4),0) -> 202509 | E4: 예) 202509 → CY 당월 = 이 달, UY 누적 = 이 달 마감까지
B5: UY 계약 시작월 | C5: 202506 | D5: =IFERROR(--TRIM(C5),0) -> 202506 | E5: 예) 202506 → UY 누적 대상 계약년월의 시작
B6: 손해율 Top20 최소 보험료 비중 | C6: 0.0005 | E6: 보험료가 아주 작은 담보 제외용 (보통 그대로 두세요, 0이면 제한 없음)
D7: =D4-100 -> 202409
D8: =D5-100 -> 202406
B10: ② 매월 작업 순서
B11: 1) 위 노란 칸에 기준월(예: 202509)과 UY 계약 시작월(예: 202506)을 입력
B12: 2) 로데이터 넣기 — 매크로 [LoadRawData] 실행 → 파일 선택 (기존 데이터는 자동 삭제)
B13: 매크로를 못 쓰면: raw_data 시트 전체 삭제 → A1에 헤더 포함 10개 열 붙여넣기 (값 붙여넣기)
B14: ※ 로데이터에는 당해 구간과 전년 동기 구간(예: 202406~202409)이 모두 있어야 증감이 계산됨
B15: 3) 아래 ③ 데이터 점검의 '종합 상태'가 정상인지 확인
B16: 4) 워드 리포트 — 매크로 [MakeWordReport] 실행 → 이 파일과 같은 폴더에 docx 생성
B17: 매크로를 못 쓰면: '요약', 'Top20' 시트의 표를 복사해 워드에 붙여넣기(원본 서식 유지)
B18: 담보 마스터가 바뀐 경우에만: code_master 시트 A~C열(담보코드·담보명·대급부명) 교체 (최대 1,000개 자동 반영)
B20: ③ 데이터 점검 (자동)
B21: 점검 항목 | C21: 결과 | D21: 상태 | E21: 문제일 때 조치
B22: 기준월 입력 형식 | C22: =BASE_YM -> 202509 | D22: =IF(AND(BASE_YM>=190001,BASE_YM<=209912,MOD(BASE_YM,100)>=1,MOD(BASE_YM,100)<=12),"정상","오류") -> 정상 | E22: 202509처럼 6자리 숫자로 입력
B23: UY 계약 시작월 형식 | C23: =UY_START -> 202506 | D23: =IF(AND(UY_START>=190001,MOD(UY_START,100)>=1,MOD(UY_START,100)<=12,UY_START<=BASE_YM),"정상","오류") -> 정상 | E23: 6자리 숫자, 기준월보다 같거나 이전이어야 함
B24: 로데이터 행 수 | C24: =(COUNTA(raw_data!$G:$G)-1) -> 21805 | D24: =IF((COUNTA(raw_data!$G:$G)-1)>0,"정상","오류") -> 정상 | E24: raw_data 시트에 데이터가 없음 → 2) 단계 실행
B25: 로데이터 열 수 (10개) | C25: =COUNTA(raw_data!$1:$1) -> 10 | D25: =IF(COUNTA(raw_data!$1:$1)=10,"정상","확인") -> 정상 | E25: 원본 10개 열 순서대로 A~J열에 있어야 함
B26: 년월이 숫자가 아닌 행 | C26: =2*(COUNTA(raw_data!$G:$G)-1)-COUNT(raw_data!$A:$A)-COUNT(raw_data!$B:$B) -> 0 | D26: =IF(2*(COUNTA(raw_data!$G:$G)-1)-COUNT(raw_data!$A:$A)-COUNT(raw_data!$B:$B)=0,"정상","오류") -> 정상 | E26: 텍스트로 저장된 년월 → [LoadRawData]/[MakeWordReport] 매크로가 자동 변환 (수동: 데이터→텍스트 나누기→마침)
B27: 금액이 숫자가 아닌 칸 | C27: =3*(COUNTA(raw_data!$G:$G)-1)-COUNT(raw_data!$H:$H)-COUNT(raw_data!$I:$I)-COUNT(raw_data!$J:$J) -> 0 | D27: =IF(3*(COUNTA(raw_data!$G:$G)-1)-COUNT(raw_data!$H:$H)-COUNT(raw_data!$I:$I)-COUNT(raw_data!$J:$J)=0,"정상","오류") -> 정상 | E27: 위와 같음 (빈칸이면 0 입력)
B28: 년월 범위 (열 순서 확인) | C28: =MIN(raw_data!$A:$B)&" ~ "&MAX(raw_data!$A:$B) -> 202406 ~ 202509 | D28: =IF(AND(MIN(raw_data!$A:$B)>=190001,MAX(raw_data!$A:$B)<=209912),"정상","오류") -> 정상 | E28: A열=계약년월, B열=마감년월이 맞는지 확인
B29: 기준월 마감 데이터 행 수 | C29: =COUNTIF(raw_data!$B:$B,BASE_YM) -> 4362 | D29: =IF(COUNTIF(raw_data!$B:$B,BASE_YM)>0,"정상","오류") -> 정상 | E29: 기준월 입력값 또는 로데이터 기간 확인
B30: 전년 동월 마감 데이터 행 수 | C30: =COUNTIF(raw_data!$B:$B,BASE_YM_PY) -> 4360 | D30: =IF(COUNTIF(raw_data!$B:$B,BASE_YM_PY)>0,"정상","확인") -> 정상 | E30: 없으면 전년 대비 증감이 공란 → 전년 구간도 추출
B31: 심사유형이 일반/간편 외 값인 행 | C31: =(COUNTA(raw_data!$G:$G)-1)-COUNTIF(raw_data!$F:$F,"일반")-COUNTIF(raw_data!$F:$F,"간편") -> 0 | D31: =IF((COUNTA(raw_data!$G:$G)-1)-COUNTIF(raw_data!$F:$F,"일반")-COUNTIF(raw_data!$F:$F,"간편")=0,"정상","확인") -> 정상 | E31: 심사유형별 표에서 빠짐 (전사 합계에는 포함)
B32: 마스터에 없는 담보코드 행 | C32: =(COUNTA(raw_data!$G:$G)-1)-SUM(담보별집계!$AD$2:$AD$1001) -> 5 | D32: =IF((COUNTA(raw_data!$G:$G)-1)-SUM(담보별집계!$AD$2:$AD$1001)=0,"정상","확인") -> 확인 | E32: 전사 합계엔 포함, 담보별 Top20엔 빠짐 → code_master에 담보 추가
B33: 마스터 담보코드 중복 | C33: =SUM(담보별집계!$AE$2:$AE$1001) -> 0 | D33: =IF(SUM(담보별집계!$AE$2:$AE$1001)=0,"정상","오류") -> 정상 | E33: code_master에서 중복 코드 제거
B34: 마스터 담보 수 (최대 1,000) | C34: =COUNTA(code_master!$A:$A)-1 -> 545 | D34: =IF(COUNTA(code_master!$A:$A)-1<=1000,"정상","오류") -> 정상 | E34: 1,000개 초과 시 템플릿 확장 필요
B35: 대급부 종류 수 (최대 20) | C35: =COUNT(담보별집계!$AC$2:$AC$1001) -> 10 | D35: =IF(COUNT(담보별집계!$AC$2:$AC$1001)<=20,"정상","오류") -> 정상 | E35: 20종 초과 시 템플릿 확장 필요
B36: 손해율 Top20 대상 담보 수 | C36: =COUNT(담보별집계!$V$2:$V$1001) -> 380 | D36: =IF(COUNT(담보별집계!$V$2:$V$1001)>=20,"정상","확인") -> 정상 | E36: 20개 미만이면 최소 보험료 비중을 낮추기
B38: 종합 상태 | C38: =IF(COUNTIF(D22:D36,"오류")>0,"오류",IF(COUNTIF(D22:D36,"확인")>0,"확인 필요","정상")) -> 확인 필요 | E38: 정상이면 바로 보고서 생성, '확인 필요'는 내용 확인 후 진행 가능, '오류'는 반드시 조치
B40: ※ 매크로 최초 1회 설치: Alt+F11 → 파일 → 파일 가져오기 → report_macro.bas → 닫기 → 'Excel 매크로 사용 통합 문서(*.xlsm)'로 다른 이름 저장. 이후 Alt+F8로 실행.
B41: ※ 손해율 = (지급보험금 + 지급비금변동분) ÷ 위험보험료. UY 누적 = 계약년월이 [UY 시작월~기준월]이고 마감년월 ≤ 기준월인 실적 누적. CY 당월 = 마감년월 = 기준월. 전년 동기 = 12개월 전 같은 구간.

Sheet 요약
A1: =TEXT(BASE_YM,"0000\.00")&" 기준 손해율 결산 리포트" -> 2025.09 기준 손해율 결산 리포트
A2: 금액 단위: 백만원 | 손해율 = (지급보험금 + 지급비금변동분) ÷ 위험보험료 | 증감(p): 빨강 악화 / 파랑 개선
A3: =TEXT(UY_START,"0000\.00")&"~"&TEXT(BASE_YM,"0000\.00")&" 계약, "&TEXT(BASE_YM,"0000\.00")&" 마감 누적" -> 2025.06~2025.09 계약, 2025.09 마감 누적 | B3: =TEXT(BASE_YM,"0000\.00")&" 마감월" -> 2025.09 마감월
A5: 1. 핵심 요약 (전사)
A6: 구분 | B6: 위험보험료 | C6: 손해액 | D6: 손해율 | E6: 전년 손해율 | F6: 위험보험료 증감률 | G6: 손해율 증감(p)
A7: UY 누적 | B7: =SUMIFS(raw_data!$H:$H,raw_data!$A:$A,">="&UY_START,raw_data!$A:$A,"<="&BASE_YM,raw_data!$B:$B,"<="&BASE_YM) -> 20409251306 | C7: =(SUMIFS(raw_data!$I:$I,raw_data!$A:$A,">="&UY_START,raw_data!$A:$A,"<="&BASE_YM,raw_data!$B:$B,"<="&BASE_YM)+SUMIFS(raw_data!$J:$J,raw_data!$A:$A,">="&UY_START,raw_data!$A:$A,"<="&BASE_YM,raw_data!$B:$B,"<="&BASE_YM)) -> 11287776523 | D7: =IF(N(B7)=0,"",C7/B7) -> 0.55307156 | E7: =IF(N(SUMIFS(raw_data!$H:$H,raw_data!$A:$A,">="&UY_START_PY,raw_data!$A:$A,"<="&BASE_YM_PY,raw_data!$B:$B,"<="&BASE_YM_PY))=0,"",(SUMIFS(raw_data!$I:$I,raw_data!$A:$A,">="&UY_START_PY,raw_data!$A:$A,"<="&BASE_YM_PY,raw_data!$B:$B,"<="&BASE_YM_PY)+SUMIFS(raw_data!$J:$J,raw_data!$A:$A,">="&UY_START_PY,raw_data!$A:$A,"<="&BASE_YM_PY,raw_data!$B:$B,"<="&BASE_YM_PY))/SUMIFS(raw_data!$H:$H,raw_data!$A:$A,">="&UY_START_PY,raw_data!$A:$A,"<="&BASE_YM_PY,raw_data!$B:$B,"<="&BASE_YM_PY)) -> 0.56694568 | F7: =IF(N(SUMIFS(raw_data!$H:$H,raw_data!$A:$A,">="&UY_START_PY,raw_data!$A:$A,"<="&BASE_YM_PY,raw_data!$B:$B,"<="&BASE_YM_PY))=0,"",B7/SUMIFS(raw_data!$H:$H,raw_data!$A:$A,">="&UY_START_PY,raw_data!$A:$A,"<="&BASE_YM_PY,raw_data!$B:$B,"<="&BASE_YM_PY)-1) -> 0.073860053 | G7: =IF(OR(D7="",E7=""),"",D7-E7) -> -0.013874113
A8: CY 당월 | B8: =SUMIFS(raw_data!$H:$H,raw_data!$B:$B,BASE_YM) -> 8228123162 | C8: =(SUMIFS(raw_data!$I:$I,raw_data!$B:$B,BASE_YM)+SUMIFS(raw_data!$J:$J,raw_data!$B:$B,BASE_YM)) -> 5362010328 | D8: =IF(N(B8)=0,"",C8/B8) -> 0.6516687 | E8: =IF(N(SUMIFS(raw_data!$H:$H,raw_data!$B:$B,BASE_YM_PY))=0,"",(SUMIFS(raw_data!$I:$I,raw_data!$B:$B,BASE_YM_PY)+SUMIFS(raw_data!$J:$J,raw_data!$B:$B,BASE_YM_PY))/SUMIFS(raw_data!$H:$H,raw_data!$B:$B,BASE_YM_PY)) -> 0.67944834 | F8: =IF(N(SUMIFS(raw_data!$H:$H,raw_data!$B:$B,BASE_YM_PY))=0,"",B8/SUMIFS(raw_data!$H:$H,raw_data!$B:$B,BASE_YM_PY)-1) -> 0.086687225 | G8: =IF(OR(D8="",E8=""),"",D8-E8) -> -0.02777964
A9: ="※ UY 누적: "&PERIOD_UY&" (전년 "&TEXT(UY_START_PY,"0000\.00")&"~"&TEXT(BASE_YM_PY,"0000\.00")&" 계약) / CY 당월: "&PERIOD_CY&" (전년 "&TEXT(BASE_YM_PY,"0000\.00")&")" -> ※ UY 누적: 2025.06~2025.09 계약, 2025.09 마감 누적 (전년 2024.06~2024.09 계약) / CY 당월: 2025.09 마감월 (전년 2024.09)
A11: ="2. UY 누적 손해율 ("&PERIOD_UY&")" -> 2. UY 누적 손해율 (2025.06~2025.09 계약, 2025.09 마감 누적)
A12: 2-1. 심사유형별
A13: 심사유형 | B13: 위험보험료 | C13: 손해액 | D13: 손해율 | E13: 전년 손해율 | F13: 위험보험료 증감률 | G13: 손해율 증감(p)
A14: 일반 | B14: =SUMIFS(raw_data!$H:$H,raw_data!$A:$A,">="&UY_START,raw_data!$A:$A,"<="&BASE_YM,raw_data!$B:$B,"<="&BASE_YM,raw_data!$F:$F,$A14) -> 14053890547 | C14: =(SUMIFS(raw_data!$I:$I,raw_data!$A:$A,">="&UY_START,raw_data!$A:$A,"<="&BASE_YM,raw_data!$B:$B,"<="&BASE_YM,raw_data!$F:$F,$A14)+SUMIFS(raw_data!$J:$J,raw_data!$A:$A,">="&UY_START,raw_data!$A:$A,"<="&BASE_YM,raw_data!$B:$B,"<="&BASE_YM,raw_data!$F:$F,$A14)) -> 7422377958 | D14: =IF(N(B14)=0,"",C14/B14) -> 0.52813688 | E14: =IF(N(SUMIFS(raw_data!$H:$H,raw_data!$A:$A,">="&UY_START_PY,raw_data!$A:$A,"<="&BASE_YM_PY,raw_data!$B:$B,"<="&BASE_YM_PY,raw_data!$F:$F,$A14))=0,"",(SUMIFS(raw_data!$I:$I,raw_data!$A:$A,">="&UY_START_PY,raw_data!$A:$A,"<="&BASE_YM_PY,raw_data!$B:$B,"<="&BASE_YM_PY,raw_data!$F:$F,$A14)+SUMIFS(raw_data!$J:$J,raw_data!$A:$A,">="&UY_START_PY,raw_data!$A:$A,"<="&BASE_YM_PY,raw_data!$B:$B,"<="&BASE_YM_PY,raw_data!$F:$F,$A14))/SUMIFS(raw_data!$H:$H,raw_data!$A:$A,">="&UY_START_PY,raw_data!$A:$A,"<="&BASE_YM_PY,raw_data!$B:$B,"<="&BASE_YM_PY,raw_data!$F:$F,$A14)) -> 0.53939762 | F14: =IF(N(SUMIFS(raw_data!$H:$H,raw_data!$A:$A,">="&UY_START_PY,raw_data!$A:$A,"<="&BASE_YM_PY,raw_data!$B:$B,"<="&BASE_YM_PY,raw_data!$F:$F,$A14))=0,"",B14/SUMIFS(raw_data!$H:$H,raw_data!$A:$A,">="&UY_START_PY,raw_data!$A:$A,"<="&BASE_YM_PY,raw_data!$B:$B,"<="&BASE_YM_PY,raw_data!$F:$F,$A14)-1) -> 0.069831518 | G14: =IF(OR(D14="",E14=""),"",D14-E14) -> -0.011260739
A15: 간편 | B15: =SUMIFS(raw_data!$H:$H,raw_data!$A:$A,">="&UY_START,raw_data!$A:$A,"<="&BASE_YM,raw_data!$B:$B,"<="&BASE_YM,raw_data!$F:$F,$A15) -> 6355360759 | C15: =(SUMIFS(raw_data!$I:$I,raw_data!$A:$A,">="&UY_START,raw_data!$A:$A,"<="&BASE_YM,raw_data!$B:$B,"<="&BASE_YM,raw_data!$F:$F,$A15)+SUMIFS(raw_data!$J:$J,raw_data!$A:$A,">="&UY_START,raw_data!$A:$A,"<="&BASE_YM,raw_data!$B:$B,"<="&BASE_YM,raw_data!$F:$F,$A15)) -> 3865398565 | D15: =IF(N(B15)=0,"",C15/B15) -> 0.60821072 | E15: =IF(N(SUMIFS(raw_data!$H:$H,raw_data!$A:$A,">="&UY_START_PY,raw_data!$A:$A,"<="&BASE_YM_PY,raw_data!$B:$B,"<="&BASE_YM_PY,raw_data!$F:$F,$A15))=0,"",(SUMIFS(raw_data!$I:$I,raw_data!$A:$A,">="&UY_START_PY,raw_data!$A:$A,"<="&BASE_YM_PY,raw_data!$B:$B,"<="&BASE_YM_PY,raw_data!$F:$F,$A15)+SUMIFS(raw_data!$J:$J,raw_data!$A:$A,">="&UY_START_PY,raw_data!$A:$A,"<="&BASE_YM_PY,raw_data!$B:$B,"<="&BASE_YM_PY,raw_data!$F:$F,$A15))/SUMIFS(raw_data!$H:$H,raw_data!$A:$A,">="&UY_START_PY,raw_data!$A:$A,"<="&BASE_YM_PY,raw_data!$B:$B,"<="&BASE_YM_PY,raw_data!$F:$F,$A15)) -> 0.62860675 | F15: =IF(N(SUMIFS(raw_data!$H:$H,raw_data!$A:$A,">="&UY_START_PY,raw_data!$A:$A,"<="&BASE_YM_PY,raw_data!$B:$B,"<="&BASE_YM_PY,raw_data!$F:$F,$A15))=0,"",B15/SUMIFS(raw_data!$H:$H,raw_data!$A:$A,">="&UY_START_PY,raw_data!$A:$A,"<="&BASE_YM_PY,raw_data!$B:$B,"<="&BASE_YM_PY,raw_data!$F:$F,$A15)-1) -> 0.082877161 | G15: =IF(OR(D15="",E15=""),"",D15-E15) -> -0.020396026
A17: 2-2. 대급부별
A18: 대급부명 | B18: 위험보험료 | C18: 손해액 | D18: 손해율 | E18: 전년 손해율 | F18: 위험보험료 증감률 | G18: 손해율 증감(p)
A19: =IFERROR(INDEX(담보별집계!$B$2:$B$1001,MATCH(1,담보별집계!$AC$2:$AC$1001,0)),"") -> 사망 | B19: =IF($A19="","",SUMIF(담보별집계!$B$2:$B$1001,$A19,담보별집계!$D$2:$D$1001)) -> 5536867940 | C19: =IF($A19="","",SUMIF(담보별집계!$B$2:$B$1001,$A19,담보별집계!$E$2:$E$1001)) -> 2186837464 | D19: =IF(N(B19)=0,"",C19/B19) -> 0.3949593 | E19: =IF($A19="","",IF(N(SUMIF(담보별집계!$B$2:$B$1001,$A19,담보별집계!$G$2:$G$1001))=0,"",SUMIF(담보별집계!$B$2:$B$1001,$A19,담보별집계!$H$2:$H$1001)/SUMIF(담보별집계!$B$2:$B$1001,$A19,담보별집계!$G$2:$G$1001))) -> 0.40881021 | F19: =IF($A19="","",IF(N(SUMIF(담보별집계!$B$2:$B$1001,$A19,담보별집계!$G$2:$G$1001))=0,"",B19/SUMIF(담보별집계!$B$2:$B$1001,$A19,담보별집계!$G$2:$G$1001)-1)) -> 0.068950022 | G19: =IF(OR(D19="",E19=""),"",D19-E19) -> -0.013850914
A20: =IFERROR(INDEX(담보별집계!$B$2:$B$1001,MATCH(2,담보별집계!$AC$2:$AC$1001,0)),"") -> 암 | B20: =IF($A20="","",SUMIF(담보별집계!$B$2:$B$1001,$A20,담보별집계!$D$2:$D$1001)) -> 3193526051 | C20: =IF($A20="","",SUMIF(담보별집계!$B$2:$B$1001,$A20,담보별집계!$E$2:$E$1001)) -> 1775907678 | D20: =IF(N(B20)=0,"",C20/B20) -> 0.55609619 | E20: =IF($A20="","",IF(N(SUMIF(담보별집계!$B$2:$B$1001,$A20,담보별집계!$G$2:$G$1001))=0,"",SUMIF(담보별집계!$B$2:$B$1001,$A20,담보별집계!$H$2:$H$1001)/SUMIF(담보별집계!$B$2:$B$1001,$A20,담보별집계!$G$2:$G$1001))) -> 0.55414714 | F20: =IF($A20="","",IF(N(SUMIF(담보별집계!$B$2:$B$1001,$A20,담보별집계!$G$2:$G$1001))=0,"",B20/SUMIF(담보별집계!$B$2:$B$1001,$A20,담보별집계!$G$2:$G$1001)-1)) -> 0.086824419 | G20: =IF(OR(D20="",E20=""),"",D20-E20) -> 0.0019490544
A21: =IFERROR(INDEX(담보별집계!$B$2:$B$1001,MATCH(3,담보별집계!$AC$2:$AC$1001,0)),"") -> 실손의료 | B21: =IF($A21="","",SUMIF(담보별집계!$B$2:$B$1001,$A21,담보별집계!$D$2:$D$1001)) -> 2652019682 | C21: =IF($A21="","",SUMIF(담보별집계!$B$2:$B$1001,$A21,담보별집계!$E$2:$E$1001)) -> 2150573783 | D21: =IF(N(B21)=0,"",C21/B21) -> 0.81091924 | E21: =IF($A21="","",IF(N(SUMIF(담보별집계!$B$2:$B$1001,$A21,담보별집계!$G$2:$G$1001))=0,"",SUMIF(담보별집계!$B$2:$B$1001,$A21,담보별집계!$H$2:$H$1001)/SUMIF(담보별집계!$B$2:$B$1001,$A21,담보별집계!$G$2:$G$1001))) -> 0.83139685 | F21: =IF($A21="","",IF(N(SUMIF(담보별집계!$B$2:$B$1001,$A21,담보별집계!$G$2:$G$1001))=0,"",B21/SUMIF(담보별집계!$B$2:$B$1001,$A21,담보별집계!$G$2:$G$1001)-1)) -> 0.093248681 | G21: =IF(OR(D21="",E21=""),"",D21-E21) -> -0.020477607
A22: =IFERROR(INDEX(담보별집계!$B$2:$B$1001,MATCH(4,담보별집계!$AC$2:$AC$1001,0)),"") -> 수술 | B22: =IF($A22="","",SUMIF(담보별집계!$B$2:$B$1001,$A22,담보별집계!$D$2:$D$1001)) -> 2076083650 | C22: =IF($A22="","",SUMIF(담보별집계!$B$2:$B$1001,$A22,담보별집계!$E$2:$E$1001)) -> 1315107939 | D22: =IF(N(B22)=0,"",C22/B22) -> 0.63345614 | E22: =IF($A22="","",IF(N(SUMIF(담보별집계!$B$2:$B$1001,$A22,담보별집계!$G$2:$G$1001))=0,"",SUMIF(담보별집계!$B$2:$B$1001,$A22,담보별집계!$H$2:$H$1001)/SUMIF(담보별집계!$B$2:$B$1001,$A22,담보별집계!$G$2:$G$1001))) -> 0.65039469 | F22: =IF($A22="","",IF(N(SUMIF(담보별집계!$B$2:$B$1001,$A22,담보별집계!$G$2:$G$1001))=0,"",B22/SUMIF(담보별집계!$B$2:$B$1001,$A22,담보별집계!$G$2:$G$1001)-1)) -> 0.11002872 | G22: =IF(OR(D22="",E22=""),"",D22-E22) -> -0.016938548
A23: =IFERROR(INDEX(담보별집계!$B$2:$B$1001,MATCH(5,담보별집계!$AC$2:$AC$1001,0)),"") -> 심장 | B23: =IF($A23="","",SUMIF(담보별집계!$B$2:$B$1001,$A23,담보별집계!$D$2:$D$1001)) -> 1877152345 | C23: =IF($A23="","",SUMIF(담보별집계!$B$2:$B$1001,$A23,담보별집계!$E$2:$E$1001)) -> 900898467 | D23: =IF(N(B23)=0,"",C23/B23) -> 0.47992826 | E23: =IF($A23="","",IF(N(SUMIF(담보별집계!$B$2:$B$1001,$A23,담보별집계!$G$2:$G$1001))=0,"",SUMIF(담보별집계!$B$2:$B$1001,$A23,담보별집계!$H$2:$H$1001)/SUMIF(담보별집계!$B$2:$B$1001,$A23,담보별집계!$G$2:$G$1001))) -> 0.49016124 | F23: =IF($A23="","",IF(N(SUMIF(담보별집계!$B$2:$B$1001,$A23,담보별집계!$G$2:$G$1001))=0,"",B23/SUMIF(담보별집계!$B$2:$B$1001,$A23,담보별집계!$G$2:$G$1001)-1)) -> 0.093311336 | G23: =IF(OR(D23="",E23=""),"",D23-E23) -> -0.010232974
A24: =IFERROR(INDEX(담보별집계!$B$2:$B$1001,MATCH(6,담보별집계!$AC$2:$AC$1001,0)),"") -> 뇌혈관 | B24: =IF($A24="","",SUMIF(담보별집계!$B$2:$B$1001,$A24,담보별집계!$D$2:$D$1001)) -> 1651383230 | C24: =IF($A24="","",SUMIF(담보별집계!$B$2:$B$1001,$A24,담보별집계!$E$2:$E$1001)) -> 852087580 | D24: =IF(N(B24)=0,"",C24/B24) -> 0.51598415 | E24: =IF($A24="","",IF(N(SUMIF(담보별집계!$B$2:$B$1001,$A24,담보별집계!$G$2:$G$1001))=0,"",SUMIF(담보별집계!$B$2:$B$1001,$A24,담보별집계!$H$2:$H$1001)/SUMIF(담보별집계!$B$2:$B$1001,$A24,담보별집계!$G$2:$G$1001))) -> 0.48993408 | F24: =IF($A24="","",IF(N(SUMIF(담보별집계!$B$2:$B$1001,$A24,담보별집계!$G$2:$G$1001))=0,"",B24/SUMIF(담보별집계!$B$2:$B$1001,$A24,담보별집계!$G$2:$G$1001)-1)) -> 0.020341403 | G24: =IF(OR(D24="",E24=""),"",D24-E24) -> 0.026050077
A25: =IFERROR(INDEX(담보별집계!$B$2:$B$1001,MATCH(7,담보별집계!$AC$2:$AC$1001,0)),"") -> 상해 | B25: =IF($A25="","",SUMIF(담보별집계!$B$2:$B$1001,$A25,담보별집계!$D$2:$D$1001)) -> 1389037543 | C25: =IF($A25="","",SUMIF(담보별집계!$B$2:$B$1001,$A25,담보별집계!$E$2:$E$1001)) -> 875979836 | D25: =IF(N(B25)=0,"",C25/B25) -> 0.63063798 | E25: =IF($A25="","",IF(N(SUMIF(담보별집계!$B$2:$B$1001,$A25,담보별집계!$G$2:$G$1001))=0,"",SUMIF(담보별집계!$B$2:$B$1001,$A25,담보별집계!$H$2:$H$1001)/SUMIF(담보별집계!$B$2:$B$1001,$A25,담보별집계!$G$2:$G$1001))) -> 0.64935207 | F25: =IF($A25="","",IF(N(SUMIF(담보별집계!$B$2:$B$1001,$A25,담보별집계!$G$2:$G$1001))=0,"",B25/SUMIF(담보별집계!$B$2:$B$1001,$A25,담보별집계!$G$2:$G$1001)-1)) -> 0.10501514 | G25: =IF(OR(D25="",E25=""),"",D25-E25) -> -0.018714089
A26: =IFERROR(INDEX(담보별집계!$B$2:$B$1001,MATCH(8,담보별집계!$AC$2:$AC$1001,0)),"") -> 치아 | B26: =IF($A26="","",SUMIF(담보별집계!$B$2:$B$1001,$A26,담보별집계!$D$2:$D$1001)) -> 817962024 | C26: =IF($A26="","",SUMIF(담보별집계!$B$2:$B$1001,$A26,담보별집계!$E$2:$E$1001)) -> 521630515 | D26: =IF(N(B26)=0,"",C26/B26) -> 0.63771972 | E26: =IF($A26="","",IF(N(SUMIF(담보별집계!$B$2:$B$1001,$A26,담보별집계!$G$2:$G$1001))=0,"",SUMIF(담보별집계!$B$2:$B$1001,$A26,담보별집계!$H$2:$H$1001)/SUMIF(담보별집계!$B$2:$B$1001,$A26,담보별집계!$G$2:$G$1001))) -> 0.73254676 | F26: =IF($A26="","",IF(N(SUMIF(담보별집계!$B$2:$B$1001,$A26,담보별집계!$G$2:$G$1001))=0,"",B26/SUMIF(담보별집계!$B$2:$B$1001,$A26,담보별집계!$G$2:$G$1001)-1)) -> -0.12152062 | G26: =IF(OR(D26="",E26=""),"",D26-E26) -> -0.094827033
A27: =IFERROR(INDEX(담보별집계!$B$2:$B$1001,MATCH(9,담보별집계!$AC$2:$AC$1001,0)),"") -> 입원 | B27: =IF($A27="","",SUMIF(담보별집계!$B$2:$B$1001,$A27,담보별집계!$D$2:$D$1001)) -> 763493049 | C27: =IF($A27="","",SUMIF(담보별집계!$B$2:$B$1001,$A27,담보별집계!$E$2:$E$1001)) -> 520221014 | D27: =IF(N(B27)=0,"",C27/B27) -> 0.68136968 | E27: =IF($A27="","",IF(N(SUMIF(담보별집계!$B$2:$B$1001,$A27,담보별집계!$G$2:$G$1001))=0,"",SUMIF(담보별집계!$B$2:$B$1001,$A27,담보별집계!$H$2:$H$1001)/SUMIF(담보별집계!$B$2:$B$1001,$A27,담보별집계!$G$2:$G$1001))) -> 0.72636568 | F27: =IF($A27="","",IF(N(SUMIF(담보별집계!$B$2:$B$1001,$A27,담보별집계!$G$2:$G$1001))=0,"",B27/SUMIF(담보별집계!$B$2:$B$1001,$A27,담보별집계!$G$2:$G$1001)-1)) -> 0.09958335 | G27: =IF(OR(D27="",E27=""),"",D27-E27) -> -0.044995999
A28: =IFERROR(INDEX(담보별집계!$B$2:$B$1001,MATCH(10,담보별집계!$AC$2:$AC$1001,0)),"") -> 기타 | B28: =IF($A28="","",SUMIF(담보별집계!$B$2:$B$1001,$A28,담보별집계!$D$2:$D$1001)) -> 445811963 | C28: =IF($A28="","",SUMIF(담보별집계!$B$2:$B$1001,$A28,담보별집계!$E$2:$E$1001)) -> 183840943 | D28: =IF(N(B28)=0,"",C28/B28) -> 0.41237328 | E28: =IF($A28="","",IF(N(SUMIF(담보별집계!$B$2:$B$1001,$A28,담보별집계!$G$2:$G$1001))=0,"",SUMIF(담보별집계!$B$2:$B$1001,$A28,담보별집계!$H$2:$H$1001)/SUMIF(담보별집계!$B$2:$B$1001,$A28,담보별집계!$G$2:$G$1001))) -> 0.42532482 | F28: =IF($A28="","",IF(N(SUMIF(담보별집계!$B$2:$B$1001,$A28,담보별집계!$G$2:$G$1001))=0,"",B28/SUMIF(담보별집계!$B$2:$B$1001,$A28,담보별집계!$G$2:$G$1001)-1)) -> 0.19401751 | G28: =IF(OR(D28="",E28=""),"",D28-E28) -> -0.01295154
A29: =IFERROR(INDEX(담보별집계!$B$2:$B$1001,MATCH(11,담보별집계!$AC$2:$AC$1001,0)),"") | B29: =IF($A29="","",SUMIF(담보별집계!$B$2:$B$1001,$A29,담보별집계!$D$2:$D$1001)) | C29: =IF($A29="","",SUMIF(담보별집계!$B$2:$B$1001,$A29,담보별집계!$E$2:$E$1001)) | D29: =IF(N(B29)=0,"",C29/B29) | E29: =IF($A29="","",IF(N(SUMIF(담보별집계!$B$2:$B$1001,$A29,담보별집계!$G$2:$G$1001))=0,"",SUMIF(담보별집계!$B$2:$B$1001,$A29,담보별집계!$H$2:$H$1001)/SUMIF(담보별집계!$B$2:$B$1001,$A29,담보별집계!$G$2:$G$1001))) | F29: =IF($A29="","",IF(N(SUMIF(담보별집계!$B$2:$B$1001,$A29,담보별집계!$G$2:$G$1001))=0,"",B29/SUMIF(담보별집계!$B$2:$B$1001,$A29,담보별집계!$G$2:$G$1001)-1)) | G29: =IF(OR(D29="",E29=""),"",D29-E29)
A30: =IFERROR(INDEX(담보별집계!$B$2:$B$1001,MATCH(12,담보별집계!$AC$2:$AC$1001,0)),"") | B30: =IF($A30="","",SUMIF(담보별집계!$B$2:$B$1001,$A30,담보별집계!$D$2:$D$1001)) | C30: =IF($A30="","",SUMIF(담보별집계!$B$2:$B$1001,$A30,담보별집계!$E$2:$E$1001)) | D30: =IF(N(B30)=0,"",C30/B30) | E30: =IF($A30="","",IF(N(SUMIF(담보별집계!$B$2:$B$1001,$A30,담보별집계!$G$2:$G$1001))=0,"",SUMIF(담보별집계!$B$2:$B$1001,$A30,담보별집계!$H$2:$H$1001)/SUMIF(담보별집계!$B$2:$B$1001,$A30,담보별집계!$G$2:$G$1001))) | F30: =IF($A30="","",IF(N(SUMIF(담보별집계!$B$2:$B$1001,$A30,담보별집계!$G$2:$G$1001))=0,"",B30/SUMIF(담보별집계!$B$2:$B$1001,$A30,담보별집계!$G$2:$G$1001)-1)) | G30: =IF(OR(D30="",E30=""),"",D30-E30)
A31: =IFERROR(INDEX(담보별집계!$B$2:$B$1001,MATCH(13,담보별집계!$AC$2:$AC$1001,0)),"") | B31: =IF($A31="","",SUMIF(담보별집계!$B$2:$B$1001,$A31,담보별집계!$D$2:$D$1001)) | C31: =IF($A31="","",SUMIF(담보별집계!$B$2:$B$1001,$A31,담보별집계!$E$2:$E$1001)) | D31: =IF(N(B31)=0,"",C31/B31) | E31: =IF($A31="","",IF(N(SUMIF(담보별집계!$B$2:$B$1001,$A31,담보별집계!$G$2:$G$1001))=0,"",SUMIF(담보별집계!$B$2:$B$1001,$A31,담보별집계!$H$2:$H$1001)/SUMIF(담보별집계!$B$2:$B$1001,$A31,담보별집계!$G$2:$G$1001))) | F31: =IF($A31="","",IF(N(SUMIF(담보별집계!$B$2:$B$1001,$A31,담보별집계!$G$2:$G$1001))=0,"",B31/SUMIF(담보별집계!$B$2:$B$1001,$A31,담보별집계!$G$2:$G$1001)-1)) | G31: =IF(OR(D31="",E31=""),"",D31-E31)
A32: =IFERROR(INDEX(담보별집계!$B$2:$B$1001,MATCH(14,담보별집계!$AC$2:$AC$1001,0)),"") | B32: =IF($A32="","",SUMIF(담보별집계!$B$2:$B$1001,$A32,담보별집계!$D$2:$D$1001)) | C32: =IF($A32="","",SUMIF(담보별집계!$B$2:$B$1001,$A32,담보별집계!$E$2:$E$1001)) | D32: =IF(N(B32)=0,"",C32/B32) | E32: =IF($A32="","",IF(N(SUMIF(담보별집계!$B$2:$B$1001,$A32,담보별집계!$G$2:$G$1001))=0,"",SUMIF(담보별집계!$B$2:$B$1001,$A32,담보별집계!$H$2:$H$1001)/SUMIF(담보별집계!$B$2:$B$1001,$A32,담보별집계!$G$2:$G$1001))) | F32: =IF($A32="","",IF(N(SUMIF(담보별집계!$B$2:$B$1001,$A32,담보별집계!$G$2:$G$1001))=0,"",B32/SUMIF(담보별집계!$B$2:$B$1001,$A32,담보별집계!$G$2:$G$1001)-1)) | G32: =IF(OR(D32="",E32=""),"",D32-E32)
A33: =IFERROR(INDEX(담보별집계!$B$2:$B$1001,MATCH(15,담보별집계!$AC$2:$AC$1001,0)),"") | B33: =IF($A33="","",SUMIF(담보별집계!$B$2:$B$1001,$A33,담보별집계!$D$2:$D$1001)) | C33: =IF($A33="","",SUMIF(담보별집계!$B$2:$B$1001,$A33,담보별집계!$E$2:$E$1001)) | D33: =IF(N(B33)=0,"",C33/B33) | E33: =IF($A33="","",IF(N(SUMIF(담보별집계!$B$2:$B$1001,$A33,담보별집계!$G$2:$G$1001))=0,"",SUMIF(담보별집계!$B$2:$B$1001,$A33,담보별집계!$H$2:$H$1001)/SUMIF(담보별집계!$B$2:$B$1001,$A33,담보별집계!$G$2:$G$1001))) | F33: =IF($A33="","",IF(N(SUMIF(담보별집계!$B$2:$B$1001,$A33,담보별집계!$G$2:$G$1001))=0,"",B33/SUMIF(담보별집계!$B$2:$B$1001,$A33,담보별집계!$G$2:$G$1001)-1)) | G33: =IF(OR(D33="",E33=""),"",D33-E33)
A34: =IFERROR(INDEX(담보별집계!$B$2:$B$1001,MATCH(16,담보별집계!$AC$2:$AC$1001,0)),"") | B34: =IF($A34="","",SUMIF(담보별집계!$B$2:$B$1001,$A34,담보별집계!$D$2:$D$1001)) | C34: =IF($A34="","",SUMIF(담보별집계!$B$2:$B$1001,$A34,담보별집계!$E$2:$E$1001)) | D34: =IF(N(B34)=0,"",C34/B34) | E34: =IF($A34="","",IF(N(SUMIF(담보별집계!$B$2:$B$1001,$A34,담보별집계!$G$2:$G$1001))=0,"",SUMIF(담보별집계!$B$2:$B$1001,$A34,담보별집계!$H$2:$H$1001)/SUMIF(담보별집계!$B$2:$B$1001,$A34,담보별집계!$G$2:$G$1001))) | F34: =IF($A34="","",IF(N(SUMIF(담보별집계!$B$2:$B$1001,$A34,담보별집계!$G$2:$G$1001))=0,"",B34/SUMIF(담보별집계!$B$2:$B$1001,$A34,담보별집계!$G$2:$G$1001)-1)) | G34: =IF(OR(D34="",E34=""),"",D34-E34)
A35: =IFERROR(INDEX(담보별집계!$B$2:$B$1001,MATCH(17,담보별집계!$AC$2:$AC$1001,0)),"") | B35: =IF($A35="","",SUMIF(담보별집계!$B$2:$B$1001,$A35,담보별집계!$D$2:$D$1001)) | C35: =IF($A35="","",SUMIF(담보별집계!$B$2:$B$1001,$A35,담보별집계!$E$2:$E$1001)) | D35: =IF(N(B35)=0,"",C35/B35) | E35: =IF($A35="","",IF(N(SUMIF(담보별집계!$B$2:$B$1001,$A35,담보별집계!$G$2:$G$1001))=0,"",SUMIF(담보별집계!$B$2:$B$1001,$A35,담보별집계!$H$2:$H$1001)/SUMIF(담보별집계!$B$2:$B$1001,$A35,담보별집계!$G$2:$G$1001))) | F35: =IF($A35="","",IF(N(SUMIF(담보별집계!$B$2:$B$1001,$A35,담보별집계!$G$2:$G$1001))=0,"",B35/SUMIF(담보별집계!$B$2:$B$1001,$A35,담보별집계!$G$2:$G$1001)-1)) | G35: =IF(OR(D35="",E35=""),"",D35-E35)
A36: =IFERROR(INDEX(담보별집계!$B$2:$B$1001,MATCH(18,담보별집계!$AC$2:$AC$1001,0)),"") | B36: =IF($A36="","",SUMIF(담보별집계!$B$2:$B$1001,$A36,담보별집계!$D$2:$D$1001)) | C36: =IF($A36="","",SUMIF(담보별집계!$B$2:$B$1001,$A36,담보별집계!$E$2:$E$1001)) | D36: =IF(N(B36)=0,"",C36/B36) | E36: =IF($A36="","",IF(N(SUMIF(담보별집계!$B$2:$B$1001,$A36,담보별집계!$G$2:$G$1001))=0,"",SUMIF(담보별집계!$B$2:$B$1001,$A36,담보별집계!$H$2:$H$1001)/SUMIF(담보별집계!$B$2:$B$1001,$A36,담보별집계!$G$2:$G$1001))) | F36: =IF($A36="","",IF(N(SUMIF(담보별집계!$B$2:$B$1001,$A36,담보별집계!$G$2:$G$1001))=0,"",B36/SUMIF(담보별집계!$B$2:$B$1001,$A36,담보별집계!$G$2:$G$1001)-1)) | G36: =IF(OR(D36="",E36=""),"",D36-E36)
A37: =IFERROR(INDEX(담보별집계!$B$2:$B$1001,MATCH(19,담보별집계!$AC$2:$AC$1001,0)),"") | B37: =IF($A37="","",SUMIF(담보별집계!$B$2:$B$1001,$A37,담보별집계!$D$2:$D$1001)) | C37: =IF($A37="","",SUMIF(담보별집계!$B$2:$B$1001,$A37,담보별집계!$E$2:$E$1001)) | D37: =IF(N(B37)=0,"",C37/B37) | E37: =IF($A37="","",IF(N(SUMIF(담보별집계!$B$2:$B$1001,$A37,담보별집계!$G$2:$G$1001))=0,"",SUMIF(담보별집계!$B$2:$B$1001,$A37,담보별집계!$H$2:$H$1001)/SUMIF(담보별집계!$B$2:$B$1001,$A37,담보별집계!$G$2:$G$1001))) | F37: =IF($A37="","",IF(N(SUMIF(담보별집계!$B$2:$B$1001,$A37,담보별집계!$G$2:$G$1001))=0,"",B37/SUMIF(담보별집계!$B$2:$B$1001,$A37,담보별집계!$G$2:$G$1001)-1)) | G37: =IF(OR(D37="",E37=""),"",D37-E37)
A38: =IFERROR(INDEX(담보별집계!$B$2:$B$1001,MATCH(20,담보별집계!$AC$2:$AC$1001,0)),"") | B38: =IF($A38="","",SUMIF(담보별집계!$B$2:$B$1001,$A38,담보별집계!$D$2:$D$1001)) | C38: =IF($A38="","",SUMIF(담보별집계!$B$2:$B$1001,$A38,담보별집계!$E$2:$E$1001)) | D38: =IF(N(B38)=0,"",C38/B38) | E38: =IF($A38="","",IF(N(SUMIF(담보별집계!$B$2:$B$1001,$A38,담보별집계!$G$2:$G$1001))=0,"",SUMIF(담보별집계!$B$2:$B$1001,$A38,담보별집계!$H$2:$H$1001)/SUMIF(담보별집계!$B$2:$B$1001,$A38,담보별집계!$G$2:$G$1001))) | F38: =IF($A38="","",IF(N(SUMIF(담보별집계!$B$2:$B$1001,$A38,담보별집계!$G$2:$G$1001))=0,"",B38/SUMIF(담보별집계!$B$2:$B$1001,$A38,담보별집계!$G$2:$G$1001)-1)) | G38: =IF(OR(D38="",E38=""),"",D38-E38)
A39: =IF(AND(ROUND((SUMIFS(raw_data!$H:$H,raw_data!$A:$A,">="&UY_START,raw_data!$A:$A,"<="&BASE_YM,raw_data!$B:$B,"<="&BASE_YM)-SUM(담보별집계!$D$2:$D$1001)),0)=0,ROUND((SUMIFS(raw_data!$H:$H,raw_data!$A:$A,">="&UY_START_PY,raw_data!$A:$A,"<="&BASE_YM_PY,raw_data!$B:$B,"<="&BASE_YM_PY)-SUM(담보별집계!$G$2:$G$1001)),0)=0),"","(미매핑)") -> (미매핑) | B39: =IF($A39="","",(SUMIFS(raw_data!$H:$H,raw_data!$A:$A,">="&UY_START,raw_data!$A:$A,"<="&BASE_YM,raw_data!$B:$B,"<="&BASE_YM)-SUM(담보별집계!$D$2:$D$1001))) -> 5913829 | C39: =IF($A39="","",((SUMIFS(raw_data!$I:$I,raw_data!$A:$A,">="&UY_START,raw_data!$A:$A,"<="&BASE_YM,raw_data!$B:$B,"<="&BASE_YM)+SUMIFS(raw_data!$J:$J,raw_data!$A:$A,">="&UY_START,raw_data!$A:$A,"<="&BASE_YM,raw_data!$B:$B,"<="&BASE_YM))-SUM(담보별집계!$E$2:$E$1001))) -> 4691304 | D39: =IF(N(B39)=0,"",C39/B39) -> 0.79327691 | E39: =IF($A39="","",IF(N((SUMIFS(raw_data!$H:$H,raw_data!$A:$A,">="&UY_START_PY,raw_data!$A:$A,"<="&BASE_YM_PY,raw_data!$B:$B,"<="&BASE_YM_PY)-SUM(담보별집계!$G$2:$G$1001)))=0,"",((SUMIFS(raw_data!$I:$I,raw_data!$A:$A,">="&UY_START_PY,raw_data!$A:$A,"<="&BASE_YM_PY,raw_data!$B:$B,"<="&BASE_YM_PY)+SUMIFS(raw_data!$J:$J,raw_data!$A:$A,">="&UY_START_PY,raw_data!$A:$A,"<="&BASE_YM_PY,raw_data!$B:$B,"<="&BASE_YM_PY))-SUM(담보별집계!$H$2:$H$1001))/(SUMIFS(raw_data!$H:$H,raw_data!$A:$A,">="&UY_START_PY,raw_data!$A:$A,"<="&BASE_YM_PY,raw_data!$B:$B,"<="&BASE_YM_PY)-SUM(담보별집계!$G$2:$G$1001)))) | F39: =IF($A39="","",IF(N((SUMIFS(raw_data!$H:$H,raw_data!$A:$A,">="&UY_START_PY,raw_data!$A:$A,"<="&BASE_YM_PY,raw_data!$B:$B,"<="&BASE_YM_PY)-SUM(담보별집계!$G$2:$G$1001)))=0,"",B39/(SUMIFS(raw_data!$H:$H,raw_data!$A:$A,">="&UY_START_PY,raw_data!$A:$A,"<="&BASE_YM_PY,raw_data!$B:$B,"<="&BASE_YM_PY)-SUM(담보별집계!$G$2:$G$1001))-1)) | G39: =IF(OR(D39="",E39=""),"",D39-E39)
A41: ="3. CY 당월 손해율 ("&PERIOD_CY&")" -> 3. CY 당월 손해율 (2025.09 마감월)
A42: 3-1. 심사유형별
A43: 심사유형 | B43: 위험보험료 | C43: 손해액 | D43: 손해율 | E43: 전년 손해율 | F43: 위험보험료 증감률 | G43: 손해율 증감(p)
A44: 일반 | B44: =SUMIFS(raw_data!$H:$H,raw_data!$B:$B,BASE_YM,raw_data!$F:$F,$A44) -> 5668267238 | C44: =(SUMIFS(raw_data!$I:$I,raw_data!$B:$B,BASE_YM,raw_data!$F:$F,$A44)+SUMIFS(raw_data!$J:$J,raw_data!$B:$B,BASE_YM,raw_data!$F:$F,$A44)) -> 3529999362 | D44: =IF(N(B44)=0,"",C44/B44) -> 0.62276516 | E44: =IF(N(SUMIFS(raw_data!$H:$H,raw_data!$B:$B,BASE_YM_PY,raw_data!$F:$F,$A44))=0,"",(SUMIFS(raw_data!$I:$I,raw_data!$B:$B,BASE_YM_PY,raw_data!$F:$F,$A44)+SUMIFS(raw_data!$J:$J,raw_data!$B:$B,BASE_YM_PY,raw_data!$F:$F,$A44))/SUMIFS(raw_data!$H:$H,raw_data!$B:$B,BASE_YM_PY,raw_data!$F:$F,$A44)) -> 0.65068308 | F44: =IF(N(SUMIFS(raw_data!$H:$H,raw_data!$B:$B,BASE_YM_PY,raw_data!$F:$F,$A44))=0,"",B44/SUMIFS(raw_data!$H:$H,raw_data!$B:$B,BASE_YM_PY,raw_data!$F:$F,$A44)-1) -> 0.083161223 | G44: =IF(OR(D44="",E44=""),"",D44-E44) -> -0.027917919
...

Sheet Top20
A1: 담보별 Top 20 (금액 단위: 백만원)
A3: UY 누적 · 위험보험료 상위 20 담보
A4: 순위 | B4: 담보코드 | C4: 대급부명 | D4: 담보명 | E4: 위험보험료 | F4: 위험보험료 증감률 | G4: 손해율(%) | H4: 전동기 대비 증감(p)
A5: =IF($J5="","",K5) -> 1 | B5: =IF($J5="","",INDEX(담보별집계!$A$2:$A$1001,$J5)) -> CV0284 | C5: =IF($J5="","",INDEX(담보별집계!$B$2:$B$1001,$J5)) -> 암 | D5: =IF($J5="","",INDEX(담보별집계!$C$2:$C$1001,$J5)) -> 암직접치료비(20년만기) | E5: =IF($J5="","",INDEX(담보별집계!$D$2:$D$1001,$J5)) -> 482230328 | F5: =IF($J5="","",INDEX(담보별집계!$J$2:$J$1001,$J5)) -> 0.095710436 | G5: =IF($J5="","",INDEX(담보별집계!$F$2:$F$1001,$J5)) -> 0.50694378 | H5: =IF($J5="","",INDEX(담보별집계!$K$2:$K$1001,$J5)) -> -0.0017021316 | J5: =IFERROR(MATCH(K5,담보별집계!$T$2:$T$1001,0),"") -> 284 | K5: 1
A6: =IF($J6="","",K6) -> 2 | B6: =IF($J6="","",INDEX(담보별집계!$A$2:$A$1001,$J6)) -> CV0023 | C6: =IF($J6="","",INDEX(담보별집계!$B$2:$B$1001,$J6)) -> 치아 | D6: =IF($J6="","",INDEX(담보별집계!$C$2:$C$1001,$J6)) -> 보철치료비 | E6: =IF($J6="","",INDEX(담보별집계!$D$2:$D$1001,$J6)) -> 409513554 | F6: =IF($J6="","",INDEX(담보별집계!$J$2:$J$1001,$J6)) -> -0.24652761 | G6: =IF($J6="","",INDEX(담보별집계!$F$2:$F$1001,$J6)) -> 0.65231608 | H6: =IF($J6="","",INDEX(담보별집계!$K$2:$K$1001,$J6)) -> -0.14026435 | J6: =IFERROR(MATCH(K6,담보별집계!$T$2:$T$1001,0),"") -> 23 | K6: 2
A7: =IF($J7="","",K7) -> 3 | B7: =IF($J7="","",INDEX(담보별집계!$A$2:$A$1001,$J7)) -> CV0112 | C7: =IF($J7="","",INDEX(담보별집계!$B$2:$B$1001,$J7)) -> 사망 | D7: =IF($J7="","",INDEX(담보별집계!$C$2:$C$1001,$J7)) -> 재해사망(20년만기) | E7: =IF($J7="","",INDEX(담보별집계!$D$2:$D$1001,$J7)) -> 377431586 | F7: =IF($J7="","",INDEX(담보별집계!$J$2:$J$1001,$J7)) -> 0.12481095 | G7: =IF($J7="","",INDEX(담보별집계!$F$2:$F$1001,$J7)) -> 0.20157945 | H7: =IF($J7="","",INDEX(담보별집계!$K$2:$K$1001,$J7)) -> -0.0362236 | J7: =IFERROR(MATCH(K7,담보별집계!$T$2:$T$1001,0),"") -> 112 | K7: 3
A8: =IF($J8="","",K8) -> 4 | B8: =IF($J8="","",INDEX(담보별집계!$A$2:$A$1001,$J8)) -> CV0362 | C8: =IF($J8="","",INDEX(담보별집계!$B$2:$B$1001,$J8)) -> 사망 | D8: =IF($J8="","",INDEX(담보별집계!$C$2:$C$1001,$J8)) -> 상해사망(비갱신형) | E8: =IF($J8="","",INDEX(담보별집계!$D$2:$D$1001,$J8)) -> 336882807 | F8: =IF($J8="","",INDEX(담보별집계!$J$2:$J$1001,$J8)) -> 0.3073042 | G8: =IF($J8="","",INDEX(담보별집계!$F$2:$F$1001,$J8)) -> 0.31136228 | H8: =IF($J8="","",INDEX(담보별집계!$K$2:$K$1001,$J8)) -> -0.082420577 | J8: =IFERROR(MATCH(K8,담보별집계!$T$2:$T$1001,0),"") -> 362 | K8: 4
A9: =IF($J9="","",K9) -> 5 | B9: =IF($J9="","",INDEX(담보별집계!$A$2:$A$1001,$J9)) -> CV0402 | C9: =IF($J9="","",INDEX(담보별집계!$B$2:$B$1001,$J9)) -> 실손의료 | D9: =IF($J9="","",INDEX(담보별집계!$C$2:$C$1001,$J9)) -> 상해통원실손Ⅱ | E9: =IF($J9="","",INDEX(담보별집계!$D$2:$D$1001,$J9)) -> 314303274 | F9: =IF($J9="","",INDEX(담보별집계!$J$2:$J$1001,$J9)) -> 0.10469068 | G9: =IF($J9="","",INDEX(담보별집계!$F$2:$F$1001,$J9)) -> 0.58793059 | H9: =IF($J9="","",INDEX(담보별집계!$K$2:$K$1001,$J9)) -> -0.1685554 | J9: =IFERROR(MATCH(K9,담보별집계!$T$2:$T$1001,0),"") -> 402 | K9: 5
A10: =IF($J10="","",K10) -> 6 | B10: =IF($J10="","",INDEX(담보별집계!$A$2:$A$1001,$J10)) -> CV0357 | C10: =IF($J10="","",INDEX(담보별집계!$B$2:$B$1001,$J10)) -> 상해 | D10: =IF($J10="","",INDEX(담보별집계!$C$2:$C$1001,$J10)) -> 골절진단비(갱신형) | E10: =IF($J10="","",INDEX(담보별집계!$D$2:$D$1001,$J10)) -> 286373818 | F10: =IF($J10="","",INDEX(담보별집계!$J$2:$J$1001,$J10)) -> 0.11306016 | G10: =IF($J10="","",INDEX(담보별집계!$F$2:$F$1001,$J10)) -> 0.59732202 | H10: =IF($J10="","",INDEX(담보별집계!$K$2:$K$1001,$J10)) -> -0.15762657 | J10: =IFERROR(MATCH(K10,담보별집계!$T$2:$T$1001,0),"") -> 357 | K10: 6
A11: =IF($J11="","",K11) -> 7 | B11: =IF($J11="","",INDEX(담보별집계!$A$2:$A$1001,$J11)) -> CV0291 | C11: =IF($J11="","",INDEX(담보별집계!$B$2:$B$1001,$J11)) -> 실손의료 | D11: =IF($J11="","",INDEX(담보별집계!$C$2:$C$1001,$J11)) -> 상해통원실손(간편) | E11: =IF($J11="","",INDEX(담보별집계!$D$2:$D$1001,$J11)) -> 277833941 | F11: =IF($J11="","",INDEX(담보별집계!$J$2:$J$1001,$J11)) -> 0.042526985 | G11: =IF($J11="","",INDEX(담보별집계!$F$2:$F$1001,$J11)) -> 0.96744271 | H11: =IF($J11="","",INDEX(담보별집계!$K$2:$K$1001,$J11)) -> 0.030753753 | J11: =IFERROR(MATCH(K11,담보별집계!$T$2:$T$1001,0),"") -> 291 | K11: 7
A12: =IF($J12="","",K12) -> 8 | B12: =IF($J12="","",INDEX(담보별집계!$A$2:$A$1001,$J12)) -> CV0154 | C12: =IF($J12="","",INDEX(담보별집계!$B$2:$B$1001,$J12)) -> 심장 | D12: =IF($J12="","",INDEX(담보별집계!$C$2:$C$1001,$J12)) -> 허혈성심장질환진단비(간편) | E12: =IF($J12="","",INDEX(담보별집계!$D$2:$D$1001,$J12)) -> 271147484 | F12: =IF($J12="","",INDEX(담보별집계!$J$2:$J$1001,$J12)) -> -0.018609888 | G12: =IF($J12="","",INDEX(담보별집계!$F$2:$F$1001,$J12)) -> 0.44361194 | H12: =IF($J12="","",INDEX(담보별집계!$K$2:$K$1001,$J12)) -> -0.021652145 | J12: =IFERROR(MATCH(K12,담보별집계!$T$2:$T$1001,0),"") -> 154 | K12: 8
A13: =IF($J13="","",K13) -> 9 | B13: =IF($J13="","",INDEX(담보별집계!$A$2:$A$1001,$J13)) -> CV0392 | C13: =IF($J13="","",INDEX(담보별집계!$B$2:$B$1001,$J13)) -> 사망 | D13: =IF($J13="","",INDEX(담보별집계!$C$2:$C$1001,$J13)) -> 상해사망(20년만기) | E13: =IF($J13="","",INDEX(담보별집계!$D$2:$D$1001,$J13)) -> 266363499 | F13: =IF($J13="","",INDEX(담보별집계!$J$2:$J$1001,$J13)) -> -0.047762792 | G13: =IF($J13="","",INDEX(담보별집계!$F$2:$F$1001,$J13)) -> 0.44850861 | H13: =IF($J13="","",INDEX(담보별집계!$K$2:$K$1001,$J13)) -> -0.02331265 | J13: =IFERROR(MATCH(K13,담보별집계!$T$2:$T$1001,0),"") -> 392 | K13: 9
A14: =IF($J14="","",K14) -> 10 | B14: =IF($J14="","",INDEX(담보별집계!$A$2:$A$1001,$J14)) -> CV0422 | C14: =IF($J14="","",INDEX(담보별집계!$B$2:$B$1001,$J14)) -> 사망 | D14: =IF($J14="","",INDEX(담보별집계!$C$2:$C$1001,$J14)) -> 재해사망(20년만기) | E14: =IF($J14="","",INDEX(담보별집계!$D$2:$D$1001,$J14)) -> 234352815 | F14: =IF($J14="","",INDEX(담보별집계!$J$2:$J$1001,$J14)) -> 0.080841883 | G14: =IF($J14="","",INDEX(담보별집계!$F$2:$F$1001,$J14)) -> 0.2767586 | H14: =IF($J14="","",INDEX(담보별집계!$K$2:$K$1001,$J14)) -> -0.015339637 | J14: =IFERROR(MATCH(K14,담보별집계!$T$2:$T$1001,0),"") -> 422 | K14: 10
A15: =IF($J15="","",K15) -> 11 | B15: =IF($J15="","",INDEX(담보별집계!$A$2:$A$1001,$J15)) -> CV0141 | C15: =IF($J15="","",INDEX(담보별집계!$B$2:$B$1001,$J15)) -> 심장 | D15: =IF($J15="","",INDEX(담보별집계!$C$2:$C$1001,$J15)) -> 심혈관질환진단비(비갱신형) | E15: =IF($J15="","",INDEX(담보별집계!$D$2:$D$1001,$J15)) -> 224383715 | F15: =IF($J15="","",INDEX(담보별집계!$J$2:$J$1001,$J15)) -> 0.22140953 | G15: =IF($J15="","",INDEX(담보별집계!$F$2:$F$1001,$J15)) -> 0.40461669 | H15: =IF($J15="","",INDEX(담보별집계!$K$2:$K$1001,$J15)) -> -0.077196315 | J15: =IFERROR(MATCH(K15,담보별집계!$T$2:$T$1001,0),"") -> 141 | K15: 11
A16: =IF($J16="","",K16) -> 12 | B16: =IF($J16="","",INDEX(담보별집계!$A$2:$A$1001,$J16)) -> CV0234 | C16: =IF($J16="","",INDEX(담보별집계!$B$2:$B$1001,$J16)) -> 수술 | D16: =IF($J16="","",INDEX(담보별집계!$C$2:$C$1001,$J16)) -> 특정질병수술비Ⅱ | E16: =IF($J16="","",INDEX(담보별집계!$D$2:$D$1001,$J16)) -> 221739809 | F16: =IF($J16="","",INDEX(담보별집계!$J$2:$J$1001,$J16)) -> 0.19115419 | G16: =IF($J16="","",INDEX(담보별집계!$F$2:$F$1001,$J16)) -> 0.76550283 | H16: =IF($J16="","",INDEX(담보별집계!$K$2:$K$1001,$J16)) -> 0.10808499 | J16: =IFERROR(MATCH(K16,담보별집계!$T$2:$T$1001,0),"") -> 234 | K16: 12
... A24: =IF($J24="","",K24) -> 20 | B24: =IF($J24="","",INDEX(담보별집계!$A$2:$A$1001,$J24)) -> CV0086 | C24: =IF($J24="","",INDEX(담보별집계!$B$2:$B$1001,$J24)) -> 사망 | D24: =IF($J24="","",INDEX(담보별집계!$C$2:$C$1001,$J24)) -> 질병사망(20년만기) | E24: =IF($J24="","",INDEX(담보별집계!$D$2:$D$1001,$J24)) -> 156513392 | F24: =IF($J24="","",INDEX(담보별집계!$J$2:$J$1001,$J24)) -> 0.14490678 | G24: =IF($J24="","",INDEX(담보별집계!$F$2:$F$1001,$J24)) -> 0.49760039 | H24: =IF($J24="","",INDEX(담보별집계!$K$2:$K$1001,$J24)) -> 0.029045773 | J24: =IFERROR(MATCH(K24,담보별집계!$T$2:$T$1001,0),"") -> 86 | K24: 20
A27: UY 누적 · 손해율 상위 20 담보
A28: 순위 | B28: 담보코드 | C28: 대급부명 | D28: 담보명 | E28: 위험보험료 | F28: 위험보험료 증감률 | G28: 손해율(%) | H28: 전동기 대비 증감(p)
A29: =IF($J29="","",K29) -> 1 | B29: =IF($J29="","",INDEX(담보별집계!$A$2:$A$1001,$J29)) -> CV0543 | C29: =IF($J29="","",INDEX(담보별집계!$B$2:$B$1001,$J29)) -> 실손의료 | D29: =IF($J29="","",INDEX(담보별집계!$C$2:$C$1001,$J29)) -> 질병입원실손Ⅱ | E29: =IF($J29="","",INDEX(담보별집계!$D$2:$D$1001,$J29)) -> 23339768 | F29: =IF($J29="","",INDEX(담보별집계!$J$2:$J$1001,$J29)) -> -0.051053581 | G29: =IF($J29="","",INDEX(담보별집계!$F$2:$F$1001,$J29)) -> 1.5657617 | H29: =IF($J29="","",INDEX(담보별집계!$K$2:$K$1001,$J29)) -> 0.014826439 | J29: =IFERROR(MATCH(K29,담보별집계!$V$2:$V$1001,0),"") -> 543 | K29: 1
A30: =IF($J30="","",K30) -> 2 | B30: =IF($J30="","",INDEX(담보별집계!$A$2:$A$1001,$J30)) -> CV0420 | C30: =IF($J30="","",INDEX(담보별집계!$B$2:$B$1001,$J30)) -> 실손의료 | D30: =IF($J30="","",INDEX(담보별집계!$C$2:$C$1001,$J30)) -> 질병입원실손(20년만기) | E30: =IF($J30="","",INDEX(담보별집계!$D$2:$D$1001,$J30)) -> 17727837 | F30: =IF($J30="","",INDEX(담보별집계!$J$2:$J$1001,$J30)) -> 0.23920575 | G30: =IF($J30="","",INDEX(담보별집계!$F$2:$F$1001,$J30)) -> 1.4575917 | H30: =IF($J30="","",INDEX(담보별집계!$K$2:$K$1001,$J30)) -> 0.54403604 | J30: =IFERROR(MATCH(K30,담보별집계!$V$2:$V$1001,0),"") -> 420 | K30: 2
A31: =IF($J31="","",K31) -> 3 | B31: =IF($J31="","",INDEX(담보별집계!$A$2:$A$1001,$J31)) -> CV0336 | C31: =IF($J31="","",INDEX(담보별집계!$B$2:$B$1001,$J31)) -> 수술 | D31: =IF($J31="","",INDEX(담보별집계!$C$2:$C$1001,$J31)) -> 상해수술비(비갱신형) | E31: =IF($J31="","",INDEX(담보별집계!$D$2:$D$1001,$J31)) -> 10729501 | F31: =IF($J31="","",INDEX(담보별집계!$J$2:$J$1001,$J31)) -> 0.37531539 | G31: =IF($J31="","",INDEX(담보별집계!$F$2:$F$1001,$J31)) -> 1.3074616 | H31: =IF($J31="","",INDEX(담보별집계!$K$2:$K$1001,$J31)) -> 0.22305539 | J31: =IFERROR(MATCH(K31,담보별집계!$V$2:$V$1001,0),"") -> 336 | K31: 3
A32: =IF($J32="","",K32) -> 4 | B32: =IF($J32="","",INDEX(담보별집계!$A$2:$A$1001,$J32)) -> CV0406 | C32: =IF($J32="","",INDEX(담보별집계!$B$2:$B$1001,$J32)) -> 실손의료 | D32: =IF($J32="","",INDEX(담보별집계!$C$2:$C$1001,$J32)) -> 상해입원실손(간편) | E32: =IF($J32="","",INDEX(담보별집계!$D$2:$D$1001,$J32)) -> 47388754 | F32: =IF($J32="","",INDEX(담보별집계!$J$2:$J$1001,$J32)) -> -0.15637779 | G32: =IF($J32="","",INDEX(담보별집계!$F$2:$F$1001,$J32)) -> 1.2778622 | H32: =IF($J32="","",INDEX(담보별집계!$K$2:$K$1001,$J32)) -> 0.19934698 | J32: =IFERROR(MATCH(K32,담보별집계!$V$2:$V$1001,0),"") -> 406 | K32: 4
A33: =IF($J33="","",K33) -> 5 | B33: =IF($J33="","",INDEX(담보별집계!$A$2:$A$1001,$J33)) -> CV0061 | C33: =IF($J33="","",INDEX(담보별집계!$B$2:$B$1001,$J33)) -> 수술 | D33: =IF($J33="","",INDEX(담보별집계!$C$2:$C$1001,$J33)) -> 1~5종수술비Ⅱ | E33: =IF($J33="","",INDEX(담보별집계!$D$2:$D$1001,$J33)) -> 20009296 | F33: =IF($J33="","",INDEX(담보별집계!$J$2:$J$1001,$J33)) -> 0.049146619 | G33: =IF($J33="","",INDEX(담보별집계!$F$2:$F$1001,$J33)) -> 1.2476808 | H33: =IF($J33="","",INDEX(담보별집계!$K$2:$K$1001,$J33)) -> -0.11635183 | J33: =IFERROR(MATCH(K33,담보별집계!$V$2:$V$1001,0),"") -> 61 | K33: 5
A34: =IF($J34="","",K34) -> 6 | B34: =IF($J34="","",INDEX(담보별집계!$A$2:$A$1001,$J34)) -> CV0003 | C34: =IF($J34="","",INDEX(담보별집계!$B$2:$B$1001,$J34)) -> 실손의료 | D34: =IF($J34="","",INDEX(담보별집계!$C$2:$C$1001,$J34)) -> 질병통원실손 | E34: =IF($J34="","",INDEX(담보별집계!$D$2:$D$1001,$J34)) -> 36894923 | F34: =IF($J34="","",INDEX(담보별집계!$J$2:$J$1001,$J34)) -> 0.30494303 | G34: =IF($J34="","",INDEX(담보별집계!$F$2:$F$1001,$J34)) -> 1.1411641 | H34: =IF($J34="","",INDEX(담보별집계!$K$2:$K$1001,$J34)) -> -0.010854226 | J34: =IFERROR(MATCH(K34,담보별집계!$V$2:$V$1001,0),"") -> 3 | K34: 6
A35: =IF($J35="","",K35) -> 7 | B35: =IF($J35="","",INDEX(담보별집계!$A$2:$A$1001,$J35)) -> CV0507 | C35: =IF($J35="","",INDEX(담보별집계!$B$2:$B$1001,$J35)) -> 암 | D35: =IF($J35="","",INDEX(담보별집계!$C$2:$C$1001,$J35)) -> 암진단비 | E35: =IF($J35="","",INDEX(담보별집계!$D$2:$D$1001,$J35)) -> 16184375 | F35: =IF($J35="","",INDEX(담보별집계!$J$2:$J$1001,$J35)) -> -0.17520403 | G35: =IF($J35="","",INDEX(담보별집계!$F$2:$F$1001,$J35)) -> 1.126451 | H35: =IF($J35="","",INDEX(담보별집계!$K$2:$K$1001,$J35)) -> 0.18405587 | J35: =IFERROR(MATCH(K35,담보별집계!$V$2:$V$1001,0),"") -> 507 | K35: 7
A36: =IF($J36="","",K36) -> 8 | B36: =IF($J36="","",INDEX(담보별집계!$A$2:$A$1001,$J36)) -> CV0174 | C36: =IF($J36="","",INDEX(담보별집계!$B$2:$B$1001,$J36)) -> 실손의료 | D36: =IF($J36="","",INDEX(담보별집계!$C$2:$C$1001,$J36)) -> 질병통원실손(간편) | E36: =IF($J36="","",INDEX(담보별집계!$D$2:$D$1001,$J36)) -> 49626274 | F36: =IF($J36="","",INDEX(담보별집계!$J$2:$J$1001,$J36)) -> 0.27702305 | G36: =IF($J36="","",INDEX(담보별집계!$F$2:$F$1001,$J36)) -> 1.1119436 | H36: =IF($J36="","",INDEX(담보별집계!$K$2:$K$1001,$J36)) -> -0.31024256 | J36: =IFERROR(MATCH(K36,담보별집계!$V$2:$V$1001,0),"") -> 174 | K36: 8
A37: =IF($J37="","",K37) -> 9 | B37: =IF($J37="","",INDEX(담보별집계!$A$2:$A$1001,$J37)) -> CV0370 | C37: =IF($J37="","",INDEX(담보별집계!$B$2:$B$1001,$J37)) -> 실손의료 | D37: =IF($J37="","",INDEX(담보별집계!$C$2:$C$1001,$J37)) -> 상해입원실손(20년만기) | E37: =IF($J37="","",INDEX(담보별집계!$D$2:$D$1001,$J37)) -> 23364152 | F37: =IF($J37="","",INDEX(담보별집계!$J$2:$J$1001,$J37)) -> 0.093124895 | G37: =IF($J37="","",INDEX(담보별집계!$F$2:$F$1001,$J37)) -> 1.0984771 | H37: =IF($J37="","",INDEX(담보별집계!$K$2:$K$1001,$J37)) -> -0.023244636 | J37: =IFERROR(MATCH(K37,담보별집계!$V$2:$V$1001,0),"") -> 370 | K37: 9
A38: =IF($J38="","",K38) -> 10 | B38: =IF($J38="","",INDEX(담보별집계!$A$2:$A$1001,$J38)) -> CV0168 | C38: =IF($J38="","",INDEX(담보별집계!$B$2:$B$1001,$J38)) -> 실손의료 | D38: =IF($J38="","",INDEX(담보별집계!$C$2:$C$1001,$J38)) -> 질병통원실손Ⅱ | E38: =IF($J38="","",INDEX(담보별집계!$D$2:$D$1001,$J38)) -> 38394622 | F38: =IF($J38="","",INDEX(담보별집계!$J$2:$J$1001,$J38)) -> 0.35208066 | G38: =IF($J38="","",INDEX(담보별집계!$F$2:$F$1001,$J38)) -> 1.05969 | H38: =IF($J38="","",INDEX(담보별집계!$K$2:$K$1001,$J38)) -> 0.0023076092 | J38: =IFERROR(MATCH(K38,담보별집계!$V$2:$V$1001,0),"") -> 168 | K38: 10
A39: =IF($J39="","",K39) -> 11 | B39: =IF($J39="","",INDEX(담보별집계!$A$2:$A$1001,$J39)) -> CV0030 | C39: =IF($J39="","",INDEX(담보별집계!$B$2:$B$1001,$J39)) -> 입원 | D39: =IF($J39="","",INDEX(담보별집계!$C$2:$C$1001,$J39)) -> 중환자실입원일당(20년만기) | E39: =IF($J39="","",INDEX(담보별집계!$D$2:$D$1001,$J39)) -> 22004986 | F39: =IF($J39="","",INDEX(담보별집계!$J$2:$J$1001,$J39)) -> 0.075486387 | G39: =IF($J39="","",INDEX(담보별집계!$F$2:$F$1001,$J39)) -> 1.0474387 | H39: =IF($J39="","",INDEX(담보별집계!$K$2:$K$1001,$J39)) -> 0.063056118 | J39: =IFERROR(MATCH(K39,담보별집계!$V$2:$V$1001,0),"") -> 30 | K39: 11
A40: =IF($J40="","",K40) -> 12 | B40: =IF($J40="","",INDEX(담보별집계!$A$2:$A$1001,$J40)) -> CV0046 | C40: =IF($J40="","",INDEX(담보별집계!$B$2:$B$1001,$J40)) -> 실손의료 | D40: =IF($J40="","",INDEX(담보별집계!$C$2:$C$1001,$J40)) -> 상해입원실손(20년만기) | E40: =IF($J40="","",INDEX(담보별집계!$D$2:$D$1001,$J40)) -> 83796719 | F40: =IF($J40="","",INDEX(담보별집계!$J$2:$J$1001,$J40)) -> 0.21772737 | G40: =IF($J40="","",INDEX(담보별집계!$F$2:$F$1001,$J40)) -> 1.0249961 | H40: =IF($J40="","",INDEX(담보별집계!$K$2:$K$1001,$J40)) -> 0.28050954 | J40: =IFERROR(MATCH(K40,담보별집계!$V$2:$V$1001,0),"") -> 46 | K40: 12
... A48: =IF($J48="","",K48) -> 20 | B48: =IF($J48="","",INDEX(담보별집계!$A$2:$A$1001,$J48)) -> CV0214 | C48: =IF($J48="","",INDEX(담보별집계!$B$2:$B$1001,$J48)) -> 실손의료 | D48: =IF($J48="","",INDEX(담보별집계!$C$2:$C$1001,$J48)) -> 질병통원실손 | E48: =IF($J48="","",INDEX(담보별집계!$D$2:$D$1001,$J48)) -> 47013107 | F48: =IF($J48="","",INDEX(담보별집계!$J$2:$J$1001,$J48)) -> 0.22617101 | G48: =IF($J48="","",INDEX(담보별집계!$F$2:$F$1001,$J48)) -> 0.9816733 | H48: =IF($J48="","",INDEX(담보별집계!$K$2:$K$1001,$J48)) -> 0.15279525 | J48: =IFERROR(MATCH(K48,담보별집계!$V$2:$V$1001,0),"") -> 214 | K48: 20
A49: ="※ 위험보험료 비중 "&TEXT(LR_MIN_SHARE,"0.00%")&" 이상 담보 대상" -> ※ 위험보험료 비중 0.05% 이상 담보 대상
A51: CY 당월 · 위험보험료 상위 20 담보
A52: 순위 | B52: 담보코드 | C52: 대급부명 | D52: 담보명 | E52: 위험보험료 | F52: 위험보험료 증감률 | G52: 손해율(%) | H52: 전동기 대비 증감(p)
A53: =IF($J53="","",K53) -> 1 | B53: =IF($J53="","",INDEX(담보별집계!$A$2:$A$1001,$J53)) -> CV0284 | C53: =IF($J53="","",INDEX(담보별집계!$B$2:$B$1001,$J53)) -> 암 | D53: =IF($J53="","",INDEX(담보별집계!$C$2:$C$1001,$J53)) -> 암직접치료비(20년만기) | E53: =IF($J53="","",INDEX(담보별집계!$L$2:$L$1001,$J53)) -> 191592971 | F53: =IF($J53="","",INDEX(담보별집계!$R$2:$R$1001,$J53)) -> 0.15958724 | G53: =IF($J53="","",INDEX(담보별집계!$N$2:$N$1001,$J53)) -> 0.51617156 | H53: =IF($J53="","",INDEX(담보별집계!$S$2:$S$1001,$J53)) -> -0.17938051 | J53: =IFERROR(MATCH(K53,담보별집계!$W$2:$W$1001,0),"") -> 284 | K53: 1
A54: =IF($J54="","",K54) -> 2 | B54: =IF($J54="","",INDEX(담보별집계!$A$2:$A$1001,$J54)) -> CV0023 | C54: =IF($J54="","",INDEX(담보별집계!$B$2:$B$1001,$J54)) -> 치아 | D54: =IF($J54="","",INDEX(담보별집계!$C$2:$C$1001,$J54)) -> 보철치료비 | E54: =IF($J54="","",INDEX(담보별집계!$L$2:$L$1001,$J54)) -> 176457672 | F54: =IF($J54="","",INDEX(담보별집계!$R$2:$R$1001,$J54)) -> -0.20405173 | G54: =IF($J54="","",INDEX(담보별집계!$N$2:$N$1001,$J54)) -> 0.78042504 | H54: =IF($J54="","",INDEX(담보별집계!$S$2:$S$1001,$J54)) -> -0.25516439 | J54: =IFERROR(MATCH(K54,담보별집계!$W$2:$W$1001,0),"") -> 23 | K54: 2
A55: =IF($J55="","",K55) -> 3 | B55: =IF($J55="","",INDEX(담보별집계!$A$2:$A$1001,$J55)) -> CV0112 | C55: =IF($J55="","",INDEX(담보별집계!$B$2:$B$1001,$J55)) -> 사망 | D55: =IF($J55="","",INDEX(담보별집계!$C$2:$C$1001,$J55)) -> 재해사망(20년만기) | E55: =IF($J55="","",INDEX(담보별집계!$L$2:$L$1001,$J55)) -> 151389650 | F55: =IF($J55="","",INDEX(담보별집계!$R$2:$R$1001,$J55)) -> 0.089247964 | G55: =IF($J55="","",INDEX(담보별집계!$N$2:$N$1001,$J55)) -> 0.2155136 | H55: =IF($J55="","",INDEX(담보별집계!$S$2:$S$1001,$J55)) -> -0.097086096 | J55: =IFERROR(MATCH(K55,담보별집계!$W$2:$W$1001,0),"") -> 112 | K55: 3
A56: =IF($J56="","",K56) -> 4 | B56: =IF($J56="","",INDEX(담보별집계!$A$2:$A$1001,$J56)) -> CV0402 | C56: =IF($J56="","",INDEX(담보별집계!$B$2:$B$1001,$J56)) -> 실손의료 | D56: =IF($J56="","",INDEX(담보별집계!$C$2:$C$1001,$J56)) -> 상해통원실손Ⅱ | E56: =IF($J56="","",INDEX(담보별집계!$L$2:$L$1001,$J56)) -> 131987648 | F56: =IF($J56="","",INDEX(담보별집계!$R$2:$R$1001,$J56)) -> 0.13953672 | G56: =IF($J56="","",INDEX(담보별집계!$N$2:$N$1001,$J56)) -> 0.63949554 | H56: =IF($J56="","",INDEX(담보별집계!$S$2:$S$1001,$J56)) -> -0.36023776 | J56: =IFERROR(MATCH(K56,담보별집계!$W$2:$W$1001,0),"") -> 402 | K56: 4
A57: =IF($J57="","",K57) -> 5 | B57: =IF($J57="","",INDEX(담보별집계!$A$2:$A$1001,$J57)) -> CV0362 | C57: =IF($J57="","",INDEX(담보별집계!$B$2:$B$1001,$J57)) -> 사망 | D57: =IF($J57="","",INDEX(담보별집계!$C$2:$C$1001,$J57)) -> 상해사망(비갱신형) | E57: =IF($J57="","",INDEX(담보별집계!$L$2:$L$1001,$J57)) -> 131539471 | F57: =IF($J57="","",INDEX(담보별집계!$R$2:$R$1001,$J57)) -> 0.29336439 | G57: =IF($J57="","",INDEX(담보별집계!$N$2:$N$1001,$J57)) -> 0.35303285 | H57: =IF($J57="","",INDEX(담보별집계!$S$2:$S$1001,$J57)) -> -0.03653624 | J57: =IFERROR(MATCH(K57,담보별집계!$W$2:$W$1001,0),"") -> 362 | K57: 5
A58: =IF($J58="","",K58) -> 6 | B58: =IF($J58="","",INDEX(담보별집계!$A$2:$A$1001,$J58)) -> CV0357 | C58: =IF($J58="","",INDEX(담보별집계!$B$2:$B$1001,$J58)) -> 상해 | D58: =IF($J58="","",INDEX(담보별집계!$C$2:$C$1001,$J58)) -> 골절진단비(갱신형) | E58: =IF($J58="","",INDEX(담보별집계!$L$2:$L$1001,$J58)) -> 120655177 | F58: =IF($J58="","",INDEX(담보별집계!$R$2:$R$1001,$J58)) -> 0.20168339 | G58: =IF($J58="","",INDEX(담보별집계!$N$2:$N$1001,$J58)) -> 0.67520416 | H58: =IF($J58="","",INDEX(담보별집계!$S$2:$S$1001,$J58)) -> -0.24987371 | J58: =IFERROR(MATCH(K58,담보별집계!$W$2:$W$1001,0),"") -> 357 | K58: 6
...

Sheet raw_data
A1: 계약년월 | B1: 마감년월 | C1: 주상품코드 | D1: 특약상품코드 | E1: 경과개월수 | F1: 심사유형(일반.간편) | G1: 담보코드 | H1: 위험보험료 합계 | I1: 지급보험금합계 | J1: 지급비금변동분 합계
A2: 202406 | B2: 202406 | C2: MP008 | D2: RP0063 | E2: 1 | F2: 일반 | G2: CV0001 | H2: 5483158 | I2: 1880910 | J2: 158645
A3: 202406 | B3: 202406 | C3: MP013 | D3: RP0083 | E3: 1 | F3: 일반 | G3: CV0002 | H3: 1091641 | I3: 526234 | J3: 55041
A4: 202406 | B4: 202406 | C4: MP002 | D4: RP0029 | E4: 1 | F4: 일반 | G4: CV0003 | H4: 2046555 | I4: 1469440 | J4: 113341
A5: 202406 | B5: 202406 | C5: MP002 | D5: RP0078 | E5: 1 | F5: 일반 | G5: CV0004 | H5: 1268341 | I5: 280109 | J5: 20935
A6: 202406 | B6: 202406 | C6: MP009 | D6: RP0054 | E6: 1 | F6: 일반 | G6: CV0005 | H6: 1787781 | I6: 198863 | J6: 28100
A7: 202406 | B7: 202406 | C7: MP014 | D7: RP0170 | E7: 1 | F7: 일반 | G7: CV0006 | H7: 990699 | I7: 338465 | J7: 8730
A8: 202406 | B8: 202406 | C8: MP007 | D8: RP0172 | E8: 1 | F8: 일반 | G8: CV0007 | H8: 7551056 | I8: 3087919 | J8: -45604
A9: 202406 | B9: 202406 | C9: MP012 | D9: RP0001 | E9: 1 | F9: 일반 | G9: CV0008 | H9: 559233 | I9: 255879 | J9: 97843
A10: 202406 | B10: 202406 | C10: MP014 | D10: RP0120 | E10: 1 | F10: 일반 | G10: CV0009 | H10: 4374706 | I10: 574673 | J10: 4835
A11: 202406 | B11: 202406 | C11: MP014 | D11: RP0128 | E11: 1 | F11: 일반 | G11: CV0010 | H11: 696094 | I11: 120878 | J11: 10881
A12: 202406 | B12: 202406 | C12: MP008 | D12: RP0076 | E12: 1 | F12: 일반 | G12: CV0011 | H12: 952080 | I12: 336535 | J12: -23411
A13: 202406 | B13: 202406 | C13: MP011 | D13: RP0094 | E13: 1 | F13: 일반 | G13: CV0012 | H13: 378552 | I13: 139532 | J13: 12788
... A21806: 202508 | B21806: 202508 | C21806: MP014 | D21806: RP0001 | E21806: 1 | F21806: 일반 | G21806: ZZ9005 | H21806: 1557514 | I21806: 465982 | J21806: -16700

Sheet code_master
A1: 담보코드 | B1: 담보명 | C1: 대급부명
A2: CV0001 | B2: 화상진단비(비갱신형) | C2: 상해
A3: CV0002 | B3: 뇌혈관질환진단비(비갱신형) | C3: 뇌혈관
A4: CV0003 | B4: 질병통원실손 | C4: 실손의료
A5: CV0004 | B5: 중환자실입원일당Ⅱ | C5: 입원
A6: CV0005 | B6: 일반사망(비갱신형) | C6: 사망
A7: CV0006 | B7: 운전자벌금(비갱신형) | C7: 기타
A8: CV0007 | B8: 깁스치료비 | C8: 상해
A9: CV0008 | B9: 골절진단비(갱신형) | C9: 상해
A10: CV0009 | B10: 일반사망(20년만기) | C10: 사망
A11: CV0010 | B11: 뇌혈관질환진단비 | C11: 뇌혈관
A12: CV0011 | B12: 암수술비(갱신형) | C12: 암
... A546: CV0545 | B546: 상해사망(비갱신형) | C546: 사망

Sheet 담보별집계
A1: 담보코드 | B1: 대급부명 | C1: 담보명 | D1: UY 위험보험료 | E1: UY 손해액 | F1: UY 손해율 | G1: UY 전년 위험보험료 | H1: UY 전년 손해액 | I1: UY 전년 손해율 | J1: UY 위험보험료 증감률 | K1: UY 손해율 증감(p) | L1: CY 위험보험료 | M1: CY 손해액 | N1: CY 손해율 | O1: CY 전년 위험보험료 | P1: CY 전년 손해액 | Q1: CY 전년 손해율 | R1: CY 위험보험료 증감률 | S1: CY 손해율 증감(p) | T1: UY 보험료순위 | U1: UY 손해율키 | V1: UY 손해율순위 | W1: CY 보험료순위 | X1: CY 손해율키 | Y1: CY 손해율순위 | AA1: 대급부 첫등장 | AB1: 대급부 UY보험료 | AC1: 대급부 순위 | AD1: 로데이터 행수 | AE1: 중복
A2: =IF(code_master!$A2="","",code_master!$A2) -> CV0001 | B2: =IF($A2="","",code_master!$C2&"") -> 상해 | C2: =IF($A2="","",code_master!$B2&"") -> 화상진단비(비갱신형) | D2: =IF($A2="","",SUMIFS(raw_data!$H:$H,raw_data!$A:$A,">="&UY_START,raw_data!$A:$A,"<="&BASE_YM,raw_data!$B:$B,"<="&BASE_YM,raw_data!$G:$G,$A2)) -> 94809130 | E2: =IF($A2="","",(SUMIFS(raw_data!$I:$I,raw_data!$A:$A,">="&UY_START,raw_data!$A:$A,"<="&BASE_YM,raw_data!$B:$B,"<="&BASE_YM,raw_data!$G:$G,$A2)+SUMIFS(raw_data!$J:$J,raw_data!$A:$A,">="&UY_START,raw_data!$A:$A,"<="&BASE_YM,raw_data!$B:$B,"<="&BASE_YM,raw_data!$G:$G,$A2))) -> 61089719 | F2: =IF(N(D2)=0,"",E2/D2) -> 0.64434426 | G2: =IF($A2="","",SUMIFS(raw_data!$H:$H,raw_data!$A:$A,">="&UY_START_PY,raw_data!$A:$A,"<="&BASE_YM_PY,raw_data!$B:$B,"<="&BASE_YM_PY,raw_data!$G:$G,$A2)) -> 97426514 | H2: =IF($A2="","",(SUMIFS(raw_data!$I:$I,raw_data!$A:$A,">="&UY_START_PY,raw_data!$A:$A,"<="&BASE_YM_PY,raw_data!$B:$B,"<="&BASE_YM_PY,raw_data!$G:$G,$A2)+SUMIFS(raw_data!$J:$J,raw_data!$A:$A,">="&UY_START_PY,raw_data!$A:$A,"<="&BASE_YM_PY,raw_data!$B:$B,"<="&BASE_YM_PY,raw_data!$G:$G,$A2))) -> 66546517 | I2: =IF(N(G2)=0,"",H2/G2) -> 0.68304319 | J2: =IF(N(G2)=0,"",D2/G2-1) -> -0.026865212 | K2: =IF(OR(F2="",I2=""),"",F2-I2) -> -0.038698928 | L2: =IF($A2="","",SUMIFS(raw_data!$H:$H,raw_data!$B:$B,BASE_YM,raw_data!$G:$G,$A2)) -> 37567646 | M2: =IF($A2="","",(SUMIFS(raw_data!$I:$I,raw_data!$B:$B,BASE_YM,raw_data!$G:$G,$A2)+SUMIFS(raw_data!$J:$J,raw_data!$B:$B,BASE_YM,raw_data!$G:$G,$A2))) -> 32798492 | N2: =IF(N(L2)=0,"",M2/L2) -> 0.87305156 | O2: =IF($A2="","",SUMIFS(raw_data!$H:$H,raw_data!$B:$B,BASE_YM_PY,raw_data!$G:$G,$A2)) -> 38881303 | P2: =IF($A2="","",(SUMIFS(raw_data!$I:$I,raw_data!$B:$B,BASE_YM_PY,raw_data!$G:$G,$A2)+SUMIFS(raw_data!$J:$J,raw_data!$B:$B,BASE_YM_PY,raw_data!$G:$G,$A2))) -> 32446447 | Q2: =IF(N(O2)=0,"",P2/O2) -> 0.83449999 | R2: =IF(N(O2)=0,"",L2/O2-1) -> -0.033786342 | S2: =IF(OR(N2="",Q2=""),"",N2-Q2) -> 0.038551571 | T2: =IF(N(D2)>0,RANK(D2,D$2:D$1001)+COUNTIF(D$2:D2,D2)-1,"") -> 51 | U2: =IF(N(D2)>0,IF(D2>=LR_MIN_SHARE*SUM(D$2:D$1001),F2,-1),-1) -> 0.64434426 | V2: =IF(U2<0,"",RANK(U2,U$2:U$1001)+COUNTIF(U$2:U2,U2)-1) -> 113 | W2: =IF(N(L2)>0,RANK(L2,L$2:L$1001)+COUNTIF(L$2:L2,L2)-1,"") -> 54 | X2: =IF(N(L2)>0,IF(L2>=LR_MIN_SHARE*SUM(L$2:L$1001),N2,-1),-1) -> 0.87305156 | Y2: =IF(X2<0,"",RANK(X2,X$2:X$1001)+COUNTIF(X$2:X2,X2)-1) -> 68 | AA2: =IF($A2="","",IF(COUNTIF($B$2:$B2,$B2)=1,1,"")) -> 1 | AB2: =IF(AA2=1,SUMIF($B$2:$B$1001,$B2,$D$2:$D$1001),"") -> 1389037543 | AC2: =IF(AA2=1,RANK(AB2,$AB$2:$AB$1001)+COUNTIF($AB$2:$AB2,AB2)-1,"") -> 7 | AD2: =IF($A2="","",COUNTIF(raw_data!$G:$G,$A2)) -> 40 | AE2: =IF($A2="","",IF(COUNTIF($A$2:$A$1001,$A2)>1,1,0)) -> 0
A3: =IF(code_master!$A3="","",code_master!$A3) -> CV0002 | B3: =IF($A3="","",code_master!$C3&"") -> 뇌혈관 | C3: =IF($A3="","",code_master!$B3&"") -> 뇌혈관질환진단비(비갱신형) | D3: =IF($A3="","",SUMIFS(raw_data!$H:$H,raw_data!$A:$A,">="&UY_START,raw_data!$A:$A,"<="&BASE_YM,raw_data!$B:$B,"<="&BASE_YM,raw_data!$G:$G,$A3)) -> 19875440 | E3: =IF($A3="","",(SUMIFS(raw_data!$I:$I,raw_data!$A:$A,">="&UY_START,raw_data!$A:$A,"<="&BASE_YM,raw_data!$B:$B,"<="&BASE_YM,raw_data!$G:$G,$A3)+SUMIFS(raw_data!$J:$J,raw_data!$A:$A,">="&UY_START,raw_data!$A:$A,"<="&BASE_YM,raw_data!$B:$B,"<="&BASE_YM,raw_data!$G:$G,$A3))) -> 15147146 | F3: =IF(N(D3)=0,"",E3/D3) -> 0.76210368 | G3: =IF($A3="","",SUMIFS(raw_data!$H:$H,raw_data!$A:$A,">="&UY_START_PY,raw_data!$A:$A,"<="&BASE_YM_PY,raw_data!$B:$B,"<="&BASE_YM_PY,raw_data!$G:$G,$A3)) -> 20828075 | H3: =IF($A3="","",(SUMIFS(raw_data!$I:$I,raw_data!$A:$A,">="&UY_START_PY,raw_data!$A:$A,"<="&BASE_YM_PY,raw_data!$B:$B,"<="&BASE_YM_PY,raw_data!$G:$G,$A3)+SUMIFS(raw_data!$J:$J,raw_data!$A:$A,">="&UY_START_PY,raw_data!$A:$A,"<="&BASE_YM_PY,raw_data!$B:$B,"<="&BASE_YM_PY,raw_data!$G:$G,$A3))) -> 15184398 | I3: =IF(N(G3)=0,"",H3/G3) -> 0.72903511 | J3: =IF(N(G3)=0,"",D3/G3-1) -> -0.045738024 | K3: =IF(OR(F3="",I3=""),"",F3-I3) -> 0.033068569 | L3: =IF($A3="","",SUMIFS(raw_data!$H:$H,raw_data!$B:$B,BASE_YM,raw_data!$G:$G,$A3)) -> 7659423 | M3: =IF($A3="","",(SUMIFS(raw_data!$I:$I,raw_data!$B:$B,BASE_YM,raw_data!$G:$G,$A3)+SUMIFS(raw_data!$J:$J,raw_data!$B:$B,BASE_YM,raw_data!$G:$G,$A3))) -> 8105427 | N3: =IF(N(L3)=0,"",M3/L3) -> 1.0582295 | O3: =IF($A3="","",SUMIFS(raw_data!$H:$H,raw_data!$B:$B,BASE_YM_PY,raw_data!$G:$G,$A3)) -> 8525850 | P3: =IF($A3="","",(SUMIFS(raw_data!$I:$I,raw_data!$B:$B,BASE_YM_PY,raw_data!$G:$G,$A3)+SUMIFS(raw_data!$J:$J,raw_data!$B:$B,BASE_YM_PY,raw_data!$G:$G,$A3))) -> 8444397 | Q3: =IF(N(O3)=0,"",P3/O3) -> 0.99044635 | R3: =IF(N(O3)=0,"",L3/O3-1) -> -0.10162353 | S3: =IF(OR(N3="",Q3=""),"",N3-Q3) -> 0.067783103 | T3: =IF(N(D3)>0,RANK(D3,D$2:D$1001)+COUNTIF(D$2:D3,D3)-1,"") -> 259 | U3: =IF(N(D3)>0,IF(D3>=LR_MIN_SHARE*SUM(D$2:D$1001),F3,-1),-1) -> 0.76210368 | V3: =IF(U3<0,"",RANK(U3,U$2:U$1001)+COUNTIF(U$2:U3,U3)-1) -> 66 | W3: =IF(N(L3)>0,RANK(L3,L$2:L$1001)+COUNTIF(L$2:L3,L3)-1,"") -> 260 | X3: =IF(N(L3)>0,IF(L3>=LR_MIN_SHARE*SUM(L$2:L$1001),N3,-1),-1) -> 1.0582295 | Y3: =IF(X3<0,"",RANK(X3,X$2:X$1001)+COUNTIF(X$2:X3,X3)-1) -> 34 | AA3: =IF($A3="","",IF(COUNTIF($B$2:$B3,$B3)=1,1,"")) -> 1 | AB3: =IF(AA3=1,SUMIF($B$2:$B$1001,$B3,$D$2:$D$1001),"") -> 1651383230 | AC3: =IF(AA3=1,RANK(AB3,$AB$2:$AB$1001)+COUNTIF($AB$2:$AB3,AB3)-1,"") -> 6 | AD3: =IF($A3="","",COUNTIF(raw_data!$G:$G,$A3)) -> 40 | AE3: =IF($A3="","",IF(COUNTIF($A$2:$A$1001,$A3)>1,1,0)) -> 0
A4: =IF(code_master!$A4="","",code_master!$A4) -> CV0003 | B4: =IF($A4="","",code_master!$C4&"") -> 실손의료 | C4: =IF($A4="","",code_master!$B4&"") -> 질병통원실손 | D4: =IF($A4="","",SUMIFS(raw_data!$H:$H,raw_data!$A:$A,">="&UY_START,raw_data!$A:$A,"<="&BASE_YM,raw_data!$B:$B,"<="&BASE_YM,raw_data!$G:$G,$A4)) -> 36894923 | E4: =IF($A4="","",(SUMIFS(raw_data!$I:$I,raw_data!$A:$A,">="&UY_START,raw_data!$A:$A,"<="&BASE_YM,raw_data!$B:$B,"<="&BASE_YM,raw_data!$G:$G,$A4)+SUMIFS(raw_data!$J:$J,raw_data!$A:$A,">="&UY_START,raw_data!$A:$A,"<="&BASE_YM,raw_data!$B:$B,"<="&BASE_YM,raw_data!$G:$G,$A4))) -> 42103161 | F4: =IF(N(D4)=0,"",E4/D4) -> 1.1411641 | G4: =IF($A4="","",SUMIFS(raw_data!$H:$H,raw_data!$A:$A,">="&UY_START_PY,raw_data!$A:$A,"<="&BASE_YM_PY,raw_data!$B:$B,"<="&BASE_YM_PY,raw_data!$G:$G,$A4)) -> 28273206 | H4: =IF($A4="","",(SUMIFS(raw_data!$I:$I,raw_data!$A:$A,">="&UY_START_PY,raw_data!$A:$A,"<="&BASE_YM_PY,raw_data!$B:$B,"<="&BASE_YM_PY,raw_data!$G:$G,$A4)+SUMIFS(raw_data!$J:$J,raw_data!$A:$A,">="&UY_START_PY,raw_data!$A:$A,"<="&BASE_YM_PY,raw_data!$B:$B,"<="&BASE_YM_PY,raw_data!$G:$G,$A4))) -> 32571251 | I4: =IF(N(G4)=0,"",H4/G4) -> 1.1520183 | J4: =IF(N(G4)=0,"",D4/G4-1) -> 0.30494303 | K4: =IF(OR(F4="",I4=""),"",F4-I4) -> -0.010854226 | L4: =IF($A4="","",SUMIFS(raw_data!$H:$H,raw_data!$B:$B,BASE_YM,raw_data!$G:$G,$A4)) -> 15326719 | M4: =IF($A4="","",(SUMIFS(raw_data!$I:$I,raw_data!$B:$B,BASE_YM,raw_data!$G:$G,$A4)+SUMIFS(raw_data!$J:$J,raw_data!$B:$B,BASE_YM,raw_data!$G:$G,$A4))) -> 20318926 | N4: =IF(N(L4)=0,"",M4/L4) -> 1.3257192 | O4: =IF($A4="","",SUMIFS(raw_data!$H:$H,raw_data!$B:$B,BASE_YM_PY,raw_data!$G:$G,$A4)) -> 10641407 | P4: =IF($A4="","",(SUMIFS(raw_data!$I:$I,raw_data!$B:$B,BASE_YM_PY,raw_data!$G:$G,$A4)+SUMIFS(raw_data!$J:$J,raw_data!$B:$B,BASE_YM_PY,raw_data!$G:$G,$A4))) -> 13964619 | Q4: =IF(N(O4)=0,"",P4/O4) -> 1.3122907 | R4: =IF(N(O4)=0,"",L4/O4-1) -> 0.44029065 | S4: =IF(OR(N4="",Q4=""),"",N4-Q4) -> 0.013428564 | T4: =IF(N(D4)>0,RANK(D4,D$2:D$1001)+COUNTIF(D$2:D4,D4)-1,"") -> 151 | U4: =IF(N(D4)>0,IF(D4>=LR_MIN_SHARE*SUM(D$2:D$1001),F4,-1),-1) -> 1.1411641 | V4: =IF(U4<0,"",RANK(U4,U$2:U$1001)+COUNTIF(U$2:U4,U4)-1) -> 6 | W4: =IF(N(L4)>0,RANK(L4,L$2:L$1001)+COUNTIF(L$2:L4,L4)-1,"") -> 151 | X4: =IF(N(L4)>0,IF(L4>=LR_MIN_SHARE*SUM(L$2:L$1001),N4,-1),-1) -> 1.3257192 | Y4: =IF(X4<0,"",RANK(X4,X$2:X$1001)+COUNTIF(X$2:X4,X4)-1) -> 11 | AA4: =IF($A4="","",IF(COUNTIF($B$2:$B4,$B4)=1,1,"")) -> 1 | AB4: =IF(AA4=1,SUMIF($B$2:$B$1001,$B4,$D$2:$D$1001),"") -> 2652019682 | AC4: =IF(AA4=1,RANK(AB4,$AB$2:$AB$1001)+COUNTIF($AB$2:$AB4,AB4)-1,"") -> 3 | AD4: =IF($A4="","",COUNTIF(raw_data!$G:$G,$A4)) -> 40 | AE4: =IF($A4="","",IF(COUNTIF($A$2:$A$1001,$A4)>1,1,0)) -> 0
A5: =IF(code_master!$A5="","",code_master!$A5) -> CV0004 | B5: =IF($A5="","",code_master!$C5&"") -> 입원 | C5: =IF($A5="","",code_master!$B5&"") -> 중환자실입원일당Ⅱ | D5: =IF($A5="","",SUMIFS(raw_data!$H:$H,raw_data!$A:$A,">="&UY_START,raw_data!$A:$A,"<="&BASE_YM,raw_data!$B:$B,"<="&BASE_YM,raw_data!$G:$G,$A5)) -> 21873545 | E5: =IF($A5="","",(SUMIFS(raw_data!$I:$I,raw_data!$A:$A,">="&UY_START,raw_data!$A:$A,"<="&BASE_YM,raw_data!$B:$B,"<="&BASE_YM,raw_data!$G:$G,$A5)+SUMIFS(raw_data!$J:$J,raw_data!$A:$A,">="&UY_START,raw_data!$A:$A,"<="&BASE_YM,raw_data!$B:$B,"<="&BASE_YM,raw_data!$G:$G,$A5))) -> 11477246 | F5: =IF(N(D5)=0,"",E5/D5) -> 0.524709 | G5: =IF($A5="","",SUMIFS(raw_data!$H:$H,raw_data!$A:$A,">="&UY_START_PY,raw_data!$A:$A,"<="&BASE_YM_PY,raw_data!$B:$B,"<="&BASE_YM_PY,raw_data!$G:$G,$A5)) -> 20110171 | H5: =IF($A5="","",(SUMIFS(raw_data!$I:$I,raw_data!$A:$A,">="&UY_START_PY,raw_data!$A:$A,"<="&BASE_YM_PY,raw_data!$B:$B,"<="&BASE_YM_PY,raw_data!$G:$G,$A5)+SUMIFS(raw_data!$J:$J,raw_data!$A:$A,">="&UY_START_PY,raw_data!$A:$A,"<="&BASE_YM_PY,raw_data!$B:$B,"<="&BASE_YM_PY,raw_data!$G:$G,$A5))) -> 12209606 | I5: =IF(N(G5)=0,"",H5/G5) -> 0.60713586 | J5: =IF(N(G5)=0,"",D5/G5-1) -> 0.087685679 | K5: =IF(OR(F5="",I5=""),"",F5-I5) -> -0.082426858 | L5: =IF($A5="","",SUMIFS(raw_data!$H:$H,raw_data!$B:$B,BASE_YM,raw_data!$G:$G,$A5)) -> 9075870 | M5: =IF($A5="","",(SUMIFS(raw_data!$I:$I,raw_data!$B:$B,BASE_YM,raw_data!$G:$G,$A5)+SUMIFS(raw_data!$J:$J,raw_data!$B:$B,BASE_YM,raw_data!$G:$G,$A5))) -> 5264523 | N5: =IF(N(L5)=0,"",M5/L5) -> 0.58005712 | O5: =IF($A5="","",SUMIFS(raw_data!$H:$H,raw_data!$B:$B,BASE_YM_PY,raw_data!$G:$G,$A5)) -> 8798800 | P5: =IF($A5="","",(SUMIFS(raw_data!$I:$I,raw_data!$B:$B,BASE_YM_PY,raw_data!$G:$G,$A5)+SUMIFS(raw_data!$J:$J,raw_data!$B:$B,BASE_YM_PY,raw_data!$G:$G,$A5))) -> 7173357 | Q5: =IF(N(O5)=0,"",P5/O5) -> 0.81526538 | R5: =IF(N(O5)=0,"",L5/O5-1) -> 0.031489521 | S5: =IF(OR(N5="",Q5=""),"",N5-Q5) -> -0.23520826 | T5: =IF(N(D5)>0,RANK(D5,D$2:D$1001)+COUNTIF(D$2:D5,D5)-1,"") -> 240 | U5: =IF(N(D5)>0,IF(D5>=LR_MIN_SHARE*SUM(D$2:D$1001),F5,-1),-1) -> 0.524709 | V5: =IF(U5<0,"",RANK(U5,U$2:U$1001)+COUNTIF(U$2:U5,U5)-1) -> 197 | W5: =IF(N(L5)>0,RANK(L5,L$2:L$1001)+COUNTIF(L$2:L5,L5)-1,"") -> 236 | X5: =IF(N(L5)>0,IF(L5>=LR_MIN_SHARE*SUM(L$2:L$1001),N5,-1),-1) -> 0.58005712 | Y5: =IF(X5<0,"",RANK(X5,X$2:X$1001)+COUNTIF(X$2:X5,X5)-1) -> 225 | AA5: =IF($A5="","",IF(COUNTIF($B$2:$B5,$B5)=1,1,"")) -> 1 | AB5: =IF(AA5=1,SUMIF($B$2:$B$1001,$B5,$D$2:$D$1001),"") -> 763493049 | AC5: =IF(AA5=1,RANK(AB5,$AB$2:$AB$1001)+COUNTIF($AB$2:$AB5,AB5)-1,"") -> 9 | AD5: =IF($A5="","",COUNTIF(raw_data!$G:$G,$A5)) -> 40 | AE5: =IF($A5="","",IF(COUNTIF($A$2:$A$1001,$A5)>1,1,0)) -> 0
